Workbook
Name xxxxxxx: #REF!
Name qzqzqz30: #REF!
Name SSSSSSSSSSSSSS: #REF!
Name csSB_VISTA_LIBRE_Dim09: #REF!
Name corte: #REF!
Name _62_0Bcer: #REF!
Name __5_0Boro: #REF!
Name Total_Occidente: #REF!
Name _25: #REF!
Name _16___0Cons: #REF!
Name Merc: #REF!
Name TEST0: #REF!
Name anex: #REF!
Name _3_0Bcer: #REF!
Name FLUJO: #REF!
Name csBA_REP_MD_EDOSFINAnchor: #REF!
Name PEDESTALESB: #REF!
Name _SM8: #REF!
Name csSB_EDO_RES_PDCT_COLOC_2_Dim08: #REF!
Name csSB_VISTA_LIBRE_Dim04: #REF!
Name sdsd: #REF!
Name CUBES_X_DIMS: #REF!
Name SALUDO: #REF!
Name TOT: #REF!
Name VENTADEBREMS: #REF!
Name __8_0Boro: #REF!
Name Panama: #REF!
Name csSB_EDO_RES_PDCT_COLOC_2_Dim09: #REF!
Name _15_0Cafo: #REF!
Name TIENDASBR: #REF!
Name data33: #REF!
Name data65: #REF!
Name aan: #REF!
Name _DAT6: #REF!
Name AÑO94: #REF!
Name TIJUANA: #REF!
Name Ventas_nales._por_cte.3: #REF!
Name C_exportar_a_Excel: #REF!
Name _713_0Cons: #REF!
Name csSB_EDO_RES_PDCT_COMIS_2_Dim09: #REF!
Name MmExcelLinker_10E3A3B8_7658_4DCF_BA7C_F7F634B86C5F: #REF!
Name OTROSPRODTOS: #REF!
Name xxxxxxxxxx: #REF!
Name JUNIO: #REF!
Name AÑO84: #REF!
Name capita_lde_trabajo: #REF!
Name RESU2: #REF!
Name __1_0Bcer: #REF!
Name _128_0Cafo: #REF!
Name CANALTHEONE: #REF!
Name PCREDITOS: #REF!
Name _130_0Cafo: #REF!
Name _7: #REF!
Name Eigenvectores: #REF!
Name _712_0Cons: #REF!
Name FECH: #REF!
Name Ajuste3: #REF!
Name _195_0Bcer: #REF!
Name Resumen_Dlls1: #REF!
Name data19: #REF!

Sheet Resumen
B1: VARIACIONES FCST REALES A MARZO VS FCST REALES A FEBRERO
B3: CONTRIBUCIÓN NETA
B5: Unidad de Negocio | C5: Plan | D5: % | F5: Fcst Reales a Feb | G5: % | H5: Fcst Reales a Mar | I5: % | K5: Var Fcst Mar vs Fcst Feb | M5: Var Fcst Mar vs Plan
B6: Research Land | C6: =+#REF! -> #REF! | D6: 0.25328689 | F6: 33.039445 | G6: 0.16262001 | H6: =#REF! -> #REF! | I6: =#REF! -> #REF! | K6: =+H6-F6 -> #REF! | M6: =+H6-C6 -> #REF!
B7: Mkt United | C7: =+'MKT UNITED 26'!AG22 -> 107.2 | D7: 0.21367058 | F7: 96.456778 | G7: 0.19961294 | H7: ='MKT UNITED 26'!O22 -> #REF! | I7: =+'MKT UNITED 26'!AJ22 -> 0% | K7: =+H7-F7 -> #REF! | M7: =+H7-C7 -> #REF!
B8: Troader | C8: =+#REF! -> #REF! | D8: 0.17652298 | F8: 7.7767062 | G8: 0.14690027 | H8: =#REF! -> #REF! | I8: =#REF! -> #REF! | K8: =+H8-F8 -> #REF! | M8: =+H8-C8 -> #REF!
B9: Zeus | C9: =+#REF! -> #REF! | D9: =#REF! -> #REF! | F9: 40.859812 | G9: 0.28328755 | H9: =+#REF! -> #REF! | I9: =#REF! -> #REF! | K9: =+H9-F9 -> #REF! | M9: =+H9-C9 -> #REF!
B10: Promo Espacio | C10: =+#REF! -> #REF! | D10: =#REF! -> #REF! | F10: 50.897038 | G10: 0.13145145 | H10: =+#REF! -> #REF! | I10: =+#REF! -> #REF! | K10: =+H10-F10 -> #REF! | M10: =+H10-C10 -> #REF!
B11: Mexa | C11: =+#REF! -> #REF! | D11: =#REF! -> #REF! | F11: 38.018213 | G11: 0.17126882 | H11: =+#REF! -> #REF! | I11: =+#REF! -> #REF! | K11: =+H11-F11 -> #REF! | M11: =+H11-C11 -> #REF!
B12: House Of Films | C12: =+#REF! -> #REF! | D12: =+#REF! -> #REF! | F12: 44.241869 | G12: 0.21917813 | H12: =+#REF! -> #REF! | I12: =#REF! -> #REF! | K12: =+H12-F12 -> #REF! | M12: =+H12-C12 -> #REF!
B13: Nera Code | C13: =+#REF! -> #REF! | D13: =+#REF! -> #REF! | F13: 45.98408 | G13: 0.1830118 | H13: =+#REF! -> #REF! | I13: =+#REF! -> #REF! | K13: =+H13-F13 -> #REF! | M13: =+H13-C13 -> #REF!
B14: UiX | C14: =+#REF! -> #REF! | D14: =+#REF! -> #REF! | F14: 26.984561 | G14: 0.21793034 | H14: =+#REF! -> #REF! | I14: =+#REF! -> #REF! | K14: =+H14-F14 -> #REF! | M14: =+H14-C14 -> #REF!
B15: Staff - ND | C15: -70.602044 | F15: -77.286247 | H15: -75.83736 | K15: =+H15-F15 -> 1.4 | M15: =+H15-C15 -> (5.2)
B17: Total | C17: =SUM(C6:C15) -> #REF! | D17: =#REF! -> #REF! | F17: =SUM(F6:F15) -> 307.0 | G17: 0.14831924 | H17: =SUM(H6:H15) -> #REF! | I17: =#REF! -> #REF! | K17: =SUM(K6:K15) -> #REF! | M17: =SUM(M6:M15) -> #REF!

Sheet MKT UNITED 26
B1: MARKETING UNITED PRESUPUESTO 2026
AE2: Real 2025 | AG2: Plan 2026 | AI2: Fcst 2026 | AK2: Conceptos | AL2: Variaciones
C3: 2 | D3: 3 | E3: 4 | F3: 5 | G3: 6 | H3: 7 | I3: 8 | J3: 9 | K3: 10 | L3: 11 | M3: 12 | N3: 13 | AL3: Fcst 2026 vs Plan 2026 | AN3: Fcst 2026 vs Real 2025
B4: Proyección | C4: 46023 | D4: 46054 | E4: 46082 | F4: 46113 | G4: 46143 | H4: 46174 | I4: 46204 | J4: 46235 | K4: 46266 | L4: 46296 | M4: 46327 | N4: 46357 | O4: Total | AE4: $ | AF4: % | AG4: $ | AH4: % | AI4: $ | AJ4: % | AL4: $ | AM4: % | AN4: $ | AO4: %
B5: Ingresos Internos | C5: 12.383028 | D5: 29.264589 | E5: 24.061369 | F5: 37.738603 | G5: 39.871111 | H5: =VLOOKUP($B5,'[1]FCST MKT UNITED 26'!$B$4:$O$22,H$3,0) -> #REF! | I5: =VLOOKUP($B5,'[1]FCST MKT UNITED 26'!$B$4:$O$22,I$3,0) -> #REF! | J5: =VLOOKUP($B5,'[1]FCST MKT UNITED 26'!$B$4:$O$22,J$3,0) -> #REF! | K5: =VLOOKUP($B5,'[1]FCST MKT UNITED 26'!$B$4:$O$22,K$3,0) -> #REF! | L5: =VLOOKUP($B5,'[1]FCST MKT UNITED 26'!$B$4:$O$22,L$3,0) -> #REF! | M5: =VLOOKUP($B5,'[1]FCST MKT UNITED 26'!$B$4:$O$22,M$3,0) -> #REF! | N5: =VLOOKUP($B5,'[1]FCST MKT UNITED 26'!$B$4:$O$22,N$3,0) -> #REF! | O5: =+SUM(C5:N5) -> #REF! | AE5: 464.32805 | AF5: =IF((+IFERROR((AE5/$AE$7),0))<=-200%,"-200%",(+IFERROR((AE5/$AE$7),0))) -> 96% | AG5: =VLOOKUP(AK5,$B$27:$O$45,14,0) -> 436.5 | AH5: =IF((+IFERROR((AG5/$AG$7),0))<=-200%,"-200%",(+IFERROR((AG5/$AG$7),0))) -> 87% | AI5: =VLOOKUP(AK5,$B$4:$O$22,14,0) -> #REF! | AJ5: =IF((+IFERROR((AI5/$AI$7),0))<=-200%,"-200%",(+IFERROR((AI5/$AI$7),0))) -> 0% | AK5: Ingresos Internos | AL5: =+AI5-AG5 -> #REF! | AM5: =IF((IFERROR(IF(ABS(AL5/AG5)>=9.99,IF(AL5>0,9.99,-9.99),AL5/ABS(AG5)),IF(AL5=0,0,AL5/ABS(AL5))))<=-200%,"-200%",(IFERROR(IF(ABS(AL5/AG5)>=9.99,IF(AL5>0,9.99,-9.99),AL5/ABS(AG5)),IF(AL5=0,0,AL5/ABS(AL5))))) -> #REF! | AN5: =AI5-AE5 -> #REF! | AO5: =IF((IFERROR(IF(ABS(AN5/AE5)>=9.99,IF(AN5>0,9.99,-9.99),AN5/ABS(AE5)),IF(AN5=0,0,AN5/ABS(AN5))))<=-200%,"(200%)",(IFERROR(IF(ABS(AN5/AE5)>=9.99,IF(AN5>0,9.99,-9.99),AN5/ABS(AE5)),IF(AN5=0,0,AN5/ABS(AN5))))) -> #REF!
B6: Ingresos Externos | C6: 4.68591 | D6: 3.0455318 | E6: 0.654968 | F6: 2.256396 | G6: 1.765896 | H6: =VLOOKUP($B6,'[1]FCST MKT UNITED 26'!$B$4:$O$22,H$3,0) -> #REF! | I6: =VLOOKUP($B6,'[1]FCST MKT UNITED 26'!$B$4:$O$22,I$3,0) -> #REF! | J6: =VLOOKUP($B6,'[1]FCST MKT UNITED 26'!$B$4:$O$22,J$3,0) -> #REF! | K6: =VLOOKUP($B6,'[1]FCST MKT UNITED 26'!$B$4:$O$22,K$3,0) -> #REF! | L6: =VLOOKUP($B6,'[1]FCST MKT UNITED 26'!$B$4:$O$22,L$3,0) -> #REF! | M6: =VLOOKUP($B6,'[1]FCST MKT UNITED 26'!$B$4:$O$22,M$3,0) -> #REF! | N6: =VLOOKUP($B6,'[1]FCST MKT UNITED 26'!$B$4:$O$22,N$3,0) -> #REF! | O6: =+SUM(C6:N6) -> #REF! | AE6: 18.339807 | AF6: =IF((+IFERROR((AE6/$AE$7),0))<=-200%,"-200%",(+IFERROR((AE6/$AE$7),0))) -> 4% | AG6: =VLOOKUP(AK6,$B$27:$O$45,14,0) -> 65.0 | AH6: =IF((+IFERROR((AG6/$AG$7),0))<=-200%,"-200%",(+IFERROR((AG6/$AG$7),0))) -> 13% | AI6: =VLOOKUP(AK6,$B$4:$O$22,14,0) -> #REF! | AJ6: =IF((+IFERROR((AI6/$AI$7),0))<=-200%,"-200%",(+IFERROR((AI6/$AI$7),0))) -> 0% | AK6: Ingresos Externos | AL6: =+AI6-AG6 -> #REF! | AM6: =IF((IFERROR(IF(ABS(AL6/AG6)>=9.99,IF(AL6>0,9.99,-9.99),AL6/ABS(AG6)),IF(AL6=0,0,AL6/ABS(AL6))))<=-200%,"-200%",(IFERROR(IF(ABS(AL6/AG6)>=9.99,IF(AL6>0,9.99,-9.99),AL6/ABS(AG6)),IF(AL6=0,0,AL6/ABS(AL6))))) -> #REF! | AN6: =AI6-AE6 -> #REF! | AO6: =IF((IFERROR(IF(ABS(AN6/AE6)>=9.99,IF(AN6>0,9.99,-9.99),AN6/ABS(AE6)),IF(AN6=0,0,AN6/ABS(AN6))))<=-200%,"(200%)",(IFERROR(IF(ABS(AN6/AE6)>=9.99,IF(AN6>0,9.99,-9.99),AN6/ABS(AE6)),IF(AN6=0,0,AN6/ABS(AN6))))) -> #REF!
B7: Total Ingresos | C7: =C5+C6 -> 17.1 | D7: =D5+D6 -> 32.3 | E7: =E6+E5 -> 24.7 | F7: =F6+F5 -> 40.0 | G7: =G6+G5 -> 41.6 | H7: =H6+H5 -> #REF! | I7: =I6+I5 -> #REF! | J7: =J6+J5 -> #REF! | K7: =K6+K5 -> #REF! | L7: =L6+L5 -> #REF! | ... O7: =O6+O5 -> #REF! | AE7: =SUM(AE5:AE6) -> 482.7 | AF7: =IF((+IFERROR((AE7/$AE$7),0))<=-200%,"-200%",(+IFERROR((AE7/$AE$7),0))) -> 100% | AG7: =SUM(AG5:AG6) -> 501.5 | AH7: =IF((+IFERROR((AG7/$AG$7),0))<=-200%,"-200%",(+IFERROR((AG7/$AG$7),0))) -> 100% | AI7: =SUM(AI5:AI6) -> #REF! | AJ7: =IF((+IFERROR((AI7/$AI$7),0))<=-200%,"-200%",(+IFERROR((AI7/$AI$7),0))) -> 0% | AK7: Total Ingresos | AL7: =+AI7-AG7 -> #REF! | AM7: =IF((IFERROR(IF(ABS(AL7/AG7)>=9.99,IF(AL7>0,9.99,-9.99),AL7/ABS(AG7)),IF(AL7=0,0,AL7/ABS(AL7))))<=-200%,"-200%",(IFERROR(IF(ABS(AL7/AG7)>=9.99,IF(AL7>0,9.99,-9.99),AL7/ABS(AG7)),IF(AL7=0,0,AL7/ABS(AL7))))) -> #REF! | AN7: =AI7-AE7 -> #REF! | AO7: =IF((IFERROR(IF(ABS(AN7/AE7)>=9.99,IF(AN7>0,9.99,-9.99),AN7/ABS(AE7)),IF(AN7=0,0,AN7/ABS(AN7))))<=-200%,"(200%)",(IFERROR(IF(ABS(AN7/AE7)>=9.99,IF(AN7>0,9.99,-9.99),AN7/ABS(AE7)),IF(AN7=0,0,AN7/ABS(AN7))))) -> #REF!
A8: =#REF!/#REF! -> #REF! | B8: Activaciones | C8: -11.405566 | D8: -19.359604 | E8: -15.620091 | F8: -24.532327 | G8: -23.882503 | H8: =VLOOKUP($B8,'[1]FCST MKT UNITED 26'!$B$4:$O$22,H$3,0) -> #REF! | I8: =VLOOKUP($B8,'[1]FCST MKT UNITED 26'!$B$4:$O$22,I$3,0) -> #REF! | J8: =VLOOKUP($B8,'[1]FCST MKT UNITED 26'!$B$4:$O$22,J$3,0) -> #REF! | K8: =VLOOKUP($B8,'[1]FCST MKT UNITED 26'!$B$4:$O$22,K$3,0) -> #REF! | L8: =VLOOKUP($B8,'[1]FCST MKT UNITED 26'!$B$4:$O$22,L$3,0) -> #REF! | M8: =VLOOKUP($B8,'[1]FCST MKT UNITED 26'!$B$4:$O$22,M$3,0) -> #REF! | N8: =VLOOKUP($B8,'[1]FCST MKT UNITED 26'!$B$4:$O$22,N$3,0) -> #REF! | O8: =+SUM(C8:N8) -> #REF! | AE8: -336.06497 | AF8: =IF((+IFERROR((AE8/$AE$7),0))<=-200%,"-200%",(+IFERROR((AE8/$AE$7),0))) -> (70%) | AG8: =VLOOKUP(AK8,$B$27:$O$45,14,0) -> (300.9) | AH8: =IF((+IFERROR((AG8/$AG$7),0))<=-200%,"-200%",(+IFERROR((AG8/$AG$7),0))) -> (60%) | AI8: =VLOOKUP(AK8,$B$4:$O$22,14,0) -> #REF! | AJ8: =IF((+IFERROR((AI8/$AI$7),0))<=-200%,"-200%",(+IFERROR((AI8/$AI$7),0))) -> 0% | AK8: Activaciones | AL8: =+AI8-AG8 -> #REF! | AM8: =IF((IFERROR(IF(ABS(AL8/AG8)>=9.99,IF(AL8>0,9.99,-9.99),AL8/ABS(AG8)),IF(AL8=0,0,AL8/ABS(AL8))))<=-200%,"-200%",(IFERROR(IF(ABS(AL8/AG8)>=9.99,IF(AL8>0,9.99,-9.99),AL8/ABS(AG8)),IF(AL8=0,0,AL8/ABS(AL8))))) -> #REF! | AN8: =AI8-AE8 -> #REF! | AO8: =IF((IFERROR(IF(ABS(AN8/AE8)>=9.99,IF(AN8>0,9.99,-9.99),AN8/ABS(AE8)),IF(AN8=0,0,AN8/ABS(AN8))))<=-200%,"(200%)",(IFERROR(IF(ABS(AN8/AE8)>=9.99,IF(AN8>0,9.99,-9.99),AN8/ABS(AE8)),IF(AN8=0,0,AN8/ABS(AN8))))) -> #REF!
B9: Comisiones | C9: -0.0424585 | D9: -0.022924 | E9: -0.04886821 | F9: -0.04650403 | G9: -0.0137038 | H9: =VLOOKUP($B9,'[1]FCST MKT UNITED 26'!$B$4:$O$22,H$3,0) -> #REF! | I9: =VLOOKUP($B9,'[1]FCST MKT UNITED 26'!$B$4:$O$22,I$3,0) -> #REF! | J9: =VLOOKUP($B9,'[1]FCST MKT UNITED 26'!$B$4:$O$22,J$3,0) -> #REF! | K9: =VLOOKUP($B9,'[1]FCST MKT UNITED 26'!$B$4:$O$22,K$3,0) -> #REF! | L9: =VLOOKUP($B9,'[1]FCST MKT UNITED 26'!$B$4:$O$22,L$3,0) -> #REF! | M9: =VLOOKUP($B9,'[1]FCST MKT UNITED 26'!$B$4:$O$22,M$3,0) -> #REF! | N9: =VLOOKUP($B9,'[1]FCST MKT UNITED 26'!$B$4:$O$22,N$3,0) -> #REF! | O9: =+SUM(C9:N9) -> #REF! | P9: A partir de marzo, considerar promedio de alcance de enero y febrero | AE9: -0.44560217 | AF9: =IF((+IFERROR((AE9/$AE$7),0))<=-200%,"-200%",(+IFERROR((AE9/$AE$7),0))) -> (0%) | AG9: =VLOOKUP(AK9,$B$27:$O$45,14,0) -> (3.3) | AH9: =IF((+IFERROR((AG9/$AG$7),0))<=-200%,"-200%",(+IFERROR((AG9/$AG$7),0))) -> (1%) | AI9: =VLOOKUP(AK9,$B$4:$O$22,14,0) -> #REF! | AJ9: =IF((+IFERROR((AI9/$AI$7),0))<=-200%,"-200%",(+IFERROR((AI9/$AI$7),0))) -> 0% | AK9: Comisiones | AL9: =+AI9-AG9 -> #REF! | AM9: =IF((IFERROR(IF(ABS(AL9/AG9)>=9.99,IF(AL9>0,9.99,-9.99),AL9/ABS(AG9)),IF(AL9=0,0,AL9/ABS(AL9))))<=-200%,"-200%",(IFERROR(IF(ABS(AL9/AG9)>=9.99,IF(AL9>0,9.99,-9.99),AL9/ABS(AG9)),IF(AL9=0,0,AL9/ABS(AL9))))) -> #REF! | AN9: =AI9-AE9 -> #REF! | AO9: =IF((IFERROR(IF(ABS(AN9/AE9)>=9.99,IF(AN9>0,9.99,-9.99),AN9/ABS(AE9)),IF(AN9=0,0,AN9/ABS(AN9))))<=-200%,"(200%)",(IFERROR(IF(ABS(AN9/AE9)>=9.99,IF(AN9>0,9.99,-9.99),AN9/ABS(AE9)),IF(AN9=0,0,AN9/ABS(AN9))))) -> #REF!
B10: Participación Socios | C10: 0 | D10: 0 | E10: 0 | F10: 0 | G10: 0 | H10: =VLOOKUP($B10,'[1]FCST MKT UNITED 26'!$B$4:$O$22,H$3,0) -> #REF! | I10: =VLOOKUP($B10,'[1]FCST MKT UNITED 26'!$B$4:$O$22,I$3,0) -> #REF! | J10: =VLOOKUP($B10,'[1]FCST MKT UNITED 26'!$B$4:$O$22,J$3,0) -> #REF! | K10: =VLOOKUP($B10,'[1]FCST MKT UNITED 26'!$B$4:$O$22,K$3,0) -> #REF! | L10: =VLOOKUP($B10,'[1]FCST MKT UNITED 26'!$B$4:$O$22,L$3,0) -> #REF! | M10: =VLOOKUP($B10,'[1]FCST MKT UNITED 26'!$B$4:$O$22,M$3,0) -> #REF! | N10: =VLOOKUP($B10,'[1]FCST MKT UNITED 26'!$B$4:$O$22,N$3,0) -> #REF! | O10: =+SUM(C10:N10) -> #REF! | AE10: 0 | AF10: =IF((+IFERROR((AE10/$AE$7),0))<=-200%,"-200%",(+IFERROR((AE10/$AE$7),0))) -> 0% | AG10: =VLOOKUP(AK10,$B$27:$O$45,14,0) -> (2.3) | AH10: =IF((+IFERROR((AG10/$AG$7),0))<=-200%,"-200%",(+IFERROR((AG10/$AG$7),0))) -> (0%) | AI10: =VLOOKUP(AK10,$B$4:$O$22,14,0) -> #REF! | AJ10: =IF((+IFERROR((AI10/$AI$7),0))<=-200%,"-200%",(+IFERROR((AI10/$AI$7),0))) -> 0% | AK10: Participación Socios | AL10: =+AI10-AG10 -> #REF! | AM10: =IF((IFERROR(IF(ABS(AL10/AG10)>=9.99,IF(AL10>0,9.99,-9.99),AL10/ABS(AG10)),IF(AL10=0,0,AL10/ABS(AL10))))<=-200%,"-200%",(IFERROR(IF(ABS(AL10/AG10)>=9.99,IF(AL10>0,9.99,-9.99),AL10/ABS(AG10)),IF(AL10=0,0,AL10/ABS(AL10))))) -> #REF! | AN10: =AI10-AE10 -> #REF! | AO10: =IF((IFERROR(IF(ABS(AN10/AE10)>=9.99,IF(AN10>0,9.99,-9.99),AN10/ABS(AE10)),IF(AN10=0,0,AN10/ABS(AN10))))<=-200%,"(200%)",(IFERROR(IF(ABS(AN10/AE10)>=9.99,IF(AN10>0,9.99,-9.99),AN10/ABS(AE10)),IF(AN10=0,0,AN10/ABS(AN10))))) -> #REF!
B11: Costos Totales | C11: =SUM(C8:C10) -> (11.4) | D11: =SUM(D8:D10) -> (19.4) | E11: =SUM(E8:E10) -> (15.7) | F11: =SUM(F8:F10) -> (24.6) | G11: =SUM(G8:G10) -> (23.9) | H11: =SUM(H8:H10) -> #REF! | I11: =SUM(I8:I10) -> #REF! | J11: =SUM(J8:J10) -> #REF! | ... O11: =SUM(O8:O10) -> #REF! | AE11: =SUM(AE8:AE10) -> (336.5) | AF11: =IF((+IFERROR((AE11/$AE$7),0))<=-200%,"-200%",(+IFERROR((AE11/$AE$7),0))) -> (70%) | AG11: =SUM(AG8:AG10) -> (306.5) | AH11: =IF((+IFERROR((AG11/$AG$7),0))<=-200%,"-200%",(+IFERROR((AG11/$AG$7),0))) -> (61%) | AI11: =SUM(AI8:AI10) -> #REF! | AJ11: =IF((+IFERROR((AI11/$AI$7),0))<=-200%,"-200%",(+IFERROR((AI11/$AI$7),0))) -> 0% | AK11: Costos Totales | AL11: =+AI11-AG11 -> #REF! | AM11: =IF((IFERROR(IF(ABS(AL11/AG11)>=9.99,IF(AL11>0,9.99,-9.99),AL11/ABS(AG11)),IF(AL11=0,0,AL11/ABS(AL11))))<=-200%,"-200%",(IFERROR(IF(ABS(AL11/AG11)>=9.99,IF(AL11>0,9.99,-9.99),AL11/ABS(AG11)),IF(AL11=0,0,AL11/ABS(AL11))))) -> #REF! | AN11: =AI11-AE11 -> #REF! | AO11: =IF((IFERROR(IF(ABS(AN11/AE11)>=9.99,IF(AN11>0,9.99,-9.99),AN11/ABS(AE11)),IF(AN11=0,0,AN11/ABS(AN11))))<=-200%,"(200%)",(IFERROR(IF(ABS(AN11/AE11)>=9.99,IF(AN11>0,9.99,-9.99),AN11/ABS(AE11)),IF(AN11=0,0,AN11/ABS(AN11))))) -> #REF!
B12: Contribución Bruta | C12: =C7+C11 -> 5.6 | D12: =D7+D11 -> 12.9 | E12: =E7+E11 -> 9.0 | F12: =F7+F11 -> 15.4 | G12: =G7+G11 -> 17.7 | H12: =H7+H11 -> #REF! | I12: =I7+I11 -> #REF! | J12: =J7+J11 -> #REF! | ... O12: =O7+O11 -> #REF! | AE12: =AE11+AE7 -> 146.2 | AF12: =IF((+IFERROR((AE12/$AE$7),0))<=-200%,"-200%",(+IFERROR((AE12/$AE$7),0))) -> 30% | AG12: =AG7+AG11 -> 195.0 | AH12: =IF((+IFERROR((AG12/$AG$7),0))<=-200%,"-200%",(+IFERROR((AG12/$AG$7),0))) -> 39% | AI12: =AI7+AI11 -> #REF! | AJ12: =IF((+IFERROR((AI12/$AI$7),0))<=-200%,"-200%",(+IFERROR((AI12/$AI$7),0))) -> 0% | AK12: Contribución Bruta | AL12: =+AI12-AG12 -> #REF! | AM12: =IF((IFERROR(IF(ABS(AL12/AG12)>=9.99,IF(AL12>0,9.99,-9.99),AL12/ABS(AG12)),IF(AL12=0,0,AL12/ABS(AL12))))<=-200%,"-200%",(IFERROR(IF(ABS(AL12/AG12)>=9.99,IF(AL12>0,9.99,-9.99),AL12/ABS(AG12)),IF(AL12=0,0,AL12/ABS(AL12))))) -> #REF! | AN12: =AI12-AE12 -> #REF! | AO12: =IF((IFERROR(IF(ABS(AN12/AE12)>=9.99,IF(AN12>0,9.99,-9.99),AN12/ABS(AE12)),IF(AN12=0,0,AN12/ABS(AN12))))<=-200%,"(200%)",(IFERROR(IF(ABS(AN12/AE12)>=9.99,IF(AN12>0,9.99,-9.99),AN12/ABS(AE12)),IF(AN12=0,0,AN12/ABS(AN12))))) -> #REF!
B13: Personal | C13: -3.8888815 | D13: -3.6258446 | E13: -3.8910686 | F13: -3.8825815 | G13: -3.8703072 | H13: =VLOOKUP($B13,'[1]FCST MKT UNITED 26'!$B$4:$O$22,H$3,0) -> #REF! | I13: =VLOOKUP($B13,'[1]FCST MKT UNITED 26'!$B$4:$O$22,I$3,0) -> #REF! | J13: =VLOOKUP($B13,'[1]FCST MKT UNITED 26'!$B$4:$O$22,J$3,0) -> #REF! | K13: =VLOOKUP($B13,'[1]FCST MKT UNITED 26'!$B$4:$O$22,K$3,0) -> #REF! | L13: =VLOOKUP($B13,'[1]FCST MKT UNITED 26'!$B$4:$O$22,L$3,0) -> #REF! | M13: =VLOOKUP($B13,'[1]FCST MKT UNITED 26'!$B$4:$O$22,M$3,0) -> #REF! | N13: =VLOOKUP($B13,'[1]FCST MKT UNITED 26'!$B$4:$O$22,N$3,0) -> #REF! | O13: =+SUM(C13:N13) -> #REF! | P13: A partir de marzo, se considera el mismo monto de febrero | AE13: -39.818126 | AF13: =IF((+IFERROR((AE13/$AE$7),0))<=-200%,"-200%",(+IFERROR((AE13/$AE$7),0))) -> (8%) | AG13: =VLOOKUP(AK13,$B$27:$O$45,14,0) -> (49.6) | AH13: =IF((+IFERROR((AG13/$AG$7),0))<=-200%,"-200%",(+IFERROR((AG13/$AG$7),0))) -> (10%) | AI13: =VLOOKUP(AK13,$B$4:$O$22,14,0) -> #REF! | AJ13: =IF((+IFERROR((AI13/$AI$7),0))<=-200%,"-200%",(+IFERROR((AI13/$AI$7),0))) -> 0% | AK13: Personal | AL13: =+AI13-AG13 -> #REF! | AM13: =IF((IFERROR(IF(ABS(AL13/AG13)>=9.99,IF(AL13>0,9.99,-9.99),AL13/ABS(AG13)),IF(AL13=0,0,AL13/ABS(AL13))))<=-200%,"-200%",(IFERROR(IF(ABS(AL13/AG13)>=9.99,IF(AL13>0,9.99,-9.99),AL13/ABS(AG13)),IF(AL13=0,0,AL13/ABS(AL13))))) -> #REF! | AN13: =AI13-AE13 -> #REF! | AO13: =IF((IFERROR(IF(ABS(AN13/AE13)>=9.99,IF(AN13>0,9.99,-9.99),AN13/ABS(AE13)),IF(AN13=0,0,AN13/ABS(AN13))))<=-200%,"(200%)",(IFERROR(IF(ABS(AN13/AE13)>=9.99,IF(AN13>0,9.99,-9.99),AN13/ABS(AE13)),IF(AN13=0,0,AN13/ABS(AN13))))) -> #REF!
B14: Operación | C14: -0.52712119 | D14: -0.35311028 | E14: -0.09550295 | F14: -0.2450474 | G14: -0.24842095 | H14: =VLOOKUP($B14,'[1]FCST MKT UNITED 26'!$B$4:$O$22,H$3,0) -> #REF! | I14: =VLOOKUP($B14,'[1]FCST MKT UNITED 26'!$B$4:$O$22,I$3,0) -> #REF! | J14: =VLOOKUP($B14,'[1]FCST MKT UNITED 26'!$B$4:$O$22,J$3,0) -> #REF! | K14: =VLOOKUP($B14,'[1]FCST MKT UNITED 26'!$B$4:$O$22,K$3,0) -> #REF! | L14: =VLOOKUP($B14,'[1]FCST MKT UNITED 26'!$B$4:$O$22,L$3,0) -> #REF! | M14: =VLOOKUP($B14,'[1]FCST MKT UNITED 26'!$B$4:$O$22,M$3,0) -> #REF! | N14: =VLOOKUP($B14,'[1]FCST MKT UNITED 26'!$B$4:$O$22,N$3,0) -> #REF! | O14: =+SUM(C14:N14) -> #REF! | P14: Desde marzo queda igual que el plan en todos los meses | AE14: -4.5140742 | AF14: =IF((+IFERROR((AE14/$AE$7),0))<=-200%,"-200%",(+IFERROR((AE14/$AE$7),0))) -> (1%) | AG14: =VLOOKUP(AK14,$B$27:$O$45,14,0) -> (4.8) | AH14: =IF((+IFERROR((AG14/$AG$7),0))<=-200%,"-200%",(+IFERROR((AG14/$AG$7),0))) -> (1%) | AI14: =VLOOKUP(AK14,$B$4:$O$22,14,0) -> #REF! | AJ14: =IF((+IFERROR((AI14/$AI$7),0))<=-200%,"-200%",(+IFERROR((AI14/$AI$7),0))) -> 0% | AK14: Operación | AL14: =+AI14-AG14 -> #REF! | AM14: =IF((IFERROR(IF(ABS(AL14/AG14)>=9.99,IF(AL14>0,9.99,-9.99),AL14/ABS(AG14)),IF(AL14=0,0,AL14/ABS(AL14))))<=-200%,"-200%",(IFERROR(IF(ABS(AL14/AG14)>=9.99,IF(AL14>0,9.99,-9.99),AL14/ABS(AG14)),IF(AL14=0,0,AL14/ABS(AL14))))) -> #REF! | AN14: =AI14-AE14 -> #REF! | AO14: =IF((IFERROR(IF(ABS(AN14/AE14)>=9.99,IF(AN14>0,9.99,-9.99),AN14/ABS(AE14)),IF(AN14=0,0,AN14/ABS(AN14))))<=-200%,"(200%)",(IFERROR(IF(ABS(AN14/AE14)>=9.99,IF(AN14>0,9.99,-9.99),AN14/ABS(AE14)),IF(AN14=0,0,AN14/ABS(AN14))))) -> #REF!
B15: Mercadotecnia | C15: -0.07 | D15: -0.07403134 | E15: -0.08 | F15: -0.086 | G15: -0.08777841 | H15: =VLOOKUP($B15,'[1]FCST MKT UNITED 26'!$B$4:$O$22,H$3,0) -> #REF! | I15: =VLOOKUP($B15,'[1]FCST MKT UNITED 26'!$B$4:$O$22,I$3,0) -> #REF! | J15: =VLOOKUP($B15,'[1]FCST MKT UNITED 26'!$B$4:$O$22,J$3,0) -> #REF! | K15: =VLOOKUP($B15,'[1]FCST MKT UNITED 26'!$B$4:$O$22,K$3,0) -> #REF! | L15: =VLOOKUP($B15,'[1]FCST MKT UNITED 26'!$B$4:$O$22,L$3,0) -> #REF! | M15: =VLOOKUP($B15,'[1]FCST MKT UNITED 26'!$B$4:$O$22,M$3,0) -> #REF! | N15: =VLOOKUP($B15,'[1]FCST MKT UNITED 26'!$B$4:$O$22,N$3,0) -> #REF! | O15: =+SUM(C15:N15) -> #REF! | P15: Desde marzo queda igual que el plan en todos los meses | AE15: -2.1747093 | AF15: =IF((+IFERROR((AE15/$AE$7),0))<=-200%,"-200%",(+IFERROR((AE15/$AE$7),0))) -> (0%) | AG15: =VLOOKUP(AK15,$B$27:$O$45,14,0) -> (2.3) | AH15: =IF((+IFERROR((AG15/$AG$7),0))<=-200%,"-200%",(+IFERROR((AG15/$AG$7),0))) -> (0%) | AI15: =VLOOKUP(AK15,$B$4:$O$22,14,0) -> #REF! | AJ15: =IF((+IFERROR((AI15/$AI$7),0))<=-200%,"-200%",(+IFERROR((AI15/$AI$7),0))) -> 0% | AK15: Mercadotecnia | AL15: =+AI15-AG15 -> #REF! | AM15: =IF((IFERROR(IF(ABS(AL15/AG15)>=9.99,IF(AL15>0,9.99,-9.99),AL15/ABS(AG15)),IF(AL15=0,0,AL15/ABS(AL15))))<=-200%,"-200%",(IFERROR(IF(ABS(AL15/AG15)>=9.99,IF(AL15>0,9.99,-9.99),AL15/ABS(AG15)),IF(AL15=0,0,AL15/ABS(AL15))))) -> #REF! | AN15: =AI15-AE15 -> #REF! | AO15: =IF((IFERROR(IF(ABS(AN15/AE15)>=9.99,IF(AN15>0,9.99,-9.99),AN15/ABS(AE15)),IF(AN15=0,0,AN15/ABS(AN15))))<=-200%,"(200%)",(IFERROR(IF(ABS(AN15/AE15)>=9.99,IF(AN15>0,9.99,-9.99),AN15/ABS(AE15)),IF(AN15=0,0,AN15/ABS(AN15))))) -> #REF!
B16: Renta, Luz y Teléfono | C16: -0.39482286 | D16: -0.41314635 | E16: -0.42126174 | F16: -0.41080176 | G16: -0.4137786 | H16: =VLOOKUP($B16,'[1]FCST MKT UNITED 26'!$B$4:$O$22,H$3,0) -> #REF! | I16: =VLOOKUP($B16,'[1]FCST MKT UNITED 26'!$B$4:$O$22,I$3,0) -> #REF! | J16: =VLOOKUP($B16,'[1]FCST MKT UNITED 26'!$B$4:$O$22,J$3,0) -> #REF! | K16: =VLOOKUP($B16,'[1]FCST MKT UNITED 26'!$B$4:$O$22,K$3,0) -> #REF! | L16: =VLOOKUP($B16,'[1]FCST MKT UNITED 26'!$B$4:$O$22,L$3,0) -> #REF! | M16: =VLOOKUP($B16,'[1]FCST MKT UNITED 26'!$B$4:$O$22,M$3,0) -> #REF! | N16: =VLOOKUP($B16,'[1]FCST MKT UNITED 26'!$B$4:$O$22,N$3,0) -> #REF! | O16: =+SUM(C16:N16) -> #REF! | P16: A partir de marzo, se considera el mismo monto de febrero | AE16: -3.6057829 | AF16: =IF((+IFERROR((AE16/$AE$7),0))<=-200%,"-200%",(+IFERROR((AE16/$AE$7),0))) -> (1%) | AG16: =VLOOKUP(AK16,$B$27:$O$45,14,0) -> (4.4) | AH16: =IF((+IFERROR((AG16/$AG$7),0))<=-200%,"-200%",(+IFERROR((AG16/$AG$7),0))) -> (1%) | AI16: =VLOOKUP(AK16,$B$4:$O$22,14,0) -> #REF! | AJ16: =IF((+IFERROR((AI16/$AI$7),0))<=-200%,"-200%",(+IFERROR((AI16/$AI$7),0))) -> 0% | AK16: Renta, Luz y Teléfono | AL16: =+AI16-AG16 -> #REF! | AM16: =IF((IFERROR(IF(ABS(AL16/AG16)>=9.99,IF(AL16>0,9.99,-9.99),AL16/ABS(AG16)),IF(AL16=0,0,AL16/ABS(AL16))))<=-200%,"(200%)",(IFERROR(IF(ABS(AL16/AG16)>=9.99,IF(AL16>0,9.99,-9.99),AL16/ABS(AG16)),IF(AL16=0,0,AL16/ABS(AL16)))))*1 -> #REF! | AN16: =AI16-AE16 -> #REF! | AO16: =IF((IFERROR(IF(ABS(AN16/AE16)>=9.99,IF(AN16>0,9.99,-9.99),AN16/ABS(AE16)),IF(AN16=0,0,AN16/ABS(AN16))))<=-200%,"(200%)",(IFERROR(IF(ABS(AN16/AE16)>=9.99,IF(AN16>0,9.99,-9.99),AN16/ABS(AE16)),IF(AN16=0,0,AN16/ABS(AN16)))))*1 -> #REF!
B17: Gastos de despacho GS | C17: -0.28884766 | D17: -0.2803609 | E17: -0.27368624 | F17: -0.28761457 | G17: -0.29114064 | H17: =VLOOKUP($B17,'[1]FCST MKT UNITED 26'!$B$4:$O$22,H$3,0) -> #REF! | I17: =VLOOKUP($B17,'[1]FCST MKT UNITED 26'!$B$4:$O$22,I$3,0) -> #REF! | J17: =VLOOKUP($B17,'[1]FCST MKT UNITED 26'!$B$4:$O$22,J$3,0) -> #REF! | K17: =VLOOKUP($B17,'[1]FCST MKT UNITED 26'!$B$4:$O$22,K$3,0) -> #REF! | L17: =VLOOKUP($B17,'[1]FCST MKT UNITED 26'!$B$4:$O$22,L$3,0) -> #REF! | M17: =VLOOKUP($B17,'[1]FCST MKT UNITED 26'!$B$4:$O$22,M$3,0) -> #REF! | N17: =VLOOKUP($B17,'[1]FCST MKT UNITED 26'!$B$4:$O$22,N$3,0) -> #REF! | O17: =+SUM(C17:N17) -> #REF! | P17: A partir de marzo, se considera el mismo monto de febrero | AE17: -2.7181252 | AF17: =IF((+IFERROR((AE17/$AE$7),0))<=-200%,"-200%",(+IFERROR((AE17/$AE$7),0))) -> (1%) | AG17: =VLOOKUP(AK17,$B$27:$O$45,14,0) -> (2.6) | AH17: =IF((+IFERROR((AG17/$AG$7),0))<=-200%,"-200%",(+IFERROR((AG17/$AG$7),0))) -> (1%) | AI17: =VLOOKUP(AK17,$B$4:$O$22,14,0) -> #REF! | AJ17: =IF((+IFERROR((AI17/$AI$7),0))<=-200%,"-200%",(+IFERROR((AI17/$AI$7),0))) -> 0% | AK17: Gastos de despacho GS | AL17: =+AI17-AG17 -> #REF! | AM17: =IF((IFERROR(IF(ABS(AL17/AG17)>=9.99,IF(AL17>0,9.99,-9.99),AL17/ABS(AG17)),IF(AL17=0,0,AL17/ABS(AL17))))<=-200%,"-200%",(IFERROR(IF(ABS(AL17/AG17)>=9.99,IF(AL17>0,9.99,-9.99),AL17/ABS(AG17)),IF(AL17=0,0,AL17/ABS(AL17))))) -> #REF! | AN17: =AI17-AE17 -> #REF! | AO17: =IF((IFERROR(IF(ABS(AN17/AE17)>=9.99,IF(AN17>0,9.99,-9.99),AN17/ABS(AE17)),IF(AN17=0,0,AN17/ABS(AN17))))<=-200%,"(200%)",(IFERROR(IF(ABS(AN17/AE17)>=9.99,IF(AN17>0,9.99,-9.99),AN17/ABS(AE17)),IF(AN17=0,0,AN17/ABS(AN17))))) -> #REF!
B18: Costo de Activo | C18: -0.0001658 | D18: -0.0001688 | E18: -0.0001688 | F18: -0.0001688 | G18: -0.0001687 | H18: =VLOOKUP($B18,'[1]FCST MKT UNITED 26'!$B$4:$O$22,H$3,0) -> #REF! | I18: =VLOOKUP($B18,'[1]FCST MKT UNITED 26'!$B$4:$O$22,I$3,0) -> #REF! | J18: =VLOOKUP($B18,'[1]FCST MKT UNITED 26'!$B$4:$O$22,J$3,0) -> #REF! | K18: =VLOOKUP($B18,'[1]FCST MKT UNITED 26'!$B$4:$O$22,K$3,0) -> #REF! | L18: =VLOOKUP($B18,'[1]FCST MKT UNITED 26'!$B$4:$O$22,L$3,0) -> #REF! | M18: =VLOOKUP($B18,'[1]FCST MKT UNITED 26'!$B$4:$O$22,M$3,0) -> #REF! | N18: =VLOOKUP($B18,'[1]FCST MKT UNITED 26'!$B$4:$O$22,N$3,0) -> #REF! | O18: =+SUM(C18:N18) -> #REF! | P18: A partir de marzo, se considera el mismo monto de febrero | AE18: -0.003878325 | AF18: =IF((+IFERROR((AE18/$AE$7),0))<=-200%,"-200%",(+IFERROR((AE18/$AE$7),0))) -> (0%) | AG18: =VLOOKUP(AK18,$B$27:$O$45,14,0) -> (0.1) | AH18: =IF((+IFERROR((AG18/$AG$7),0))<=-200%,"-200%",(+IFERROR((AG18/$AG$7),0))) -> (0%) | AI18: =VLOOKUP(AK18,$B$4:$O$22,14,0) -> #REF! | AJ18: =IF((+IFERROR((AI18/$AI$7),0))<=-200%,"-200%",(+IFERROR((AI18/$AI$7),0))) -> 0% | AK18: Costo de Activo | AL18: =+AI18-AG18 -> #REF! | AM18: =IF((IFERROR(IF(ABS(AL18/AG18)>=9.99,IF(AL18>0,9.99,-9.99),AL18/ABS(AG18)),IF(AL18=0,0,AL18/ABS(AL18))))<=-200%,"-200%",(IFERROR(IF(ABS(AL18/AG18)>=9.99,IF(AL18>0,9.99,-9.99),AL18/ABS(AG18)),IF(AL18=0,0,AL18/ABS(AL18))))) -> #REF! | AN18: =AI18-AE18 -> #REF! | AO18: =IF((IFERROR(IF(ABS(AN18/AE18)>=9.99,IF(AN18>0,9.99,-9.99),AN18/ABS(AE18)),IF(AN18=0,0,AN18/ABS(AN18))))<=-200%,"(200%)",(IFERROR(IF(ABS(AN18/AE18)>=9.99,IF(AN18>0,9.99,-9.99),AN18/ABS(AE18)),IF(AN18=0,0,AN18/ABS(AN18))))) -> #REF!
B19: Gastos Ventas | C19: -0.5250295 | D19: -0.4645698 | E19: -0.3902149 | F19: -0.46456918 | G19: -0.41851421 | H19: =VLOOKUP($B19,'[1]FCST MKT UNITED 26'!$B$4:$O$22,H$3,0) -> #REF! | I19: =VLOOKUP($B19,'[1]FCST MKT UNITED 26'!$B$4:$O$22,I$3,0) -> #REF! | J19: =VLOOKUP($B19,'[1]FCST MKT UNITED 26'!$B$4:$O$22,J$3,0) -> #REF! | K19: =VLOOKUP($B19,'[1]FCST MKT UNITED 26'!$B$4:$O$22,K$3,0) -> #REF! | L19: =VLOOKUP($B19,'[1]FCST MKT UNITED 26'!$B$4:$O$22,L$3,0) -> #REF! | M19: =VLOOKUP($B19,'[1]FCST MKT UNITED 26'!$B$4:$O$22,M$3,0) -> #REF! | N19: =VLOOKUP($B19,'[1]FCST MKT UNITED 26'!$B$4:$O$22,N$3,0) -> #REF! | O19: =+SUM(C19:N19) -> #REF! | P19: A partir de marzo, se considera el mismo monto de febrero | AE19: -6.0321943 | AF19: =IF((+IFERROR((AE19/$AE$7),0))<=-200%,"-200%",(+IFERROR((AE19/$AE$7),0))) -> (1%) | AG19: =VLOOKUP(AK19,$B$27:$O$45,14,0) -> (6.1) | AH19: =IF((+IFERROR((AG19/$AG$7),0))<=-200%,"-200%",(+IFERROR((AG19/$AG$7),0))) -> (1%) | AI19: =VLOOKUP(AK19,$B$4:$O$22,14,0) -> #REF! | AJ19: =IF((+IFERROR((AI19/$AI$7),0))<=-200%,"-200%",(+IFERROR((AI19/$AI$7),0))) -> 0% | AK19: Gastos Ventas | AL19: =+AI19-AG19 -> #REF! | AM19: =IF((IFERROR(IF(ABS(AL19/AG19)>=9.99,IF(AL19>0,9.99,-9.99),AL19/ABS(AG19)),IF(AL19=0,0,AL19/ABS(AL19))))<=-200%,"-200%",(IFERROR(IF(ABS(AL19/AG19)>=9.99,IF(AL19>0,9.99,-9.99),AL19/ABS(AG19)),IF(AL19=0,0,AL19/ABS(AL19))))) -> #REF! | AN19: =AI19-AE19 -> #REF! | AO19: =IF((IFERROR(IF(ABS(AN19/AE19)>=9.99,IF(AN19>0,9.99,-9.99),AN19/ABS(AE19)),IF(AN19=0,0,AN19/ABS(AN19))))<=-200%,"(200%)",(IFERROR(IF(ABS(AN19/AE19)>=9.99,IF(AN19>0,9.99,-9.99),AN19/ABS(AE19)),IF(AN19=0,0,AN19/ABS(AN19))))) -> #REF!
B20: Gastos Staff | C20: -1.3179256 | D20: -1.4688517 | E20: -1.3427575 | F20: -1.287813 | G20: -1.3905488 | H20: =VLOOKUP($B20,'[1]FCST MKT UNITED 26'!$B$4:$O$22,H$3,0) -> #REF! | I20: =VLOOKUP($B20,'[1]FCST MKT UNITED 26'!$B$4:$O$22,I$3,0) -> #REF! | J20: =VLOOKUP($B20,'[1]FCST MKT UNITED 26'!$B$4:$O$22,J$3,0) -> #REF! | K20: =VLOOKUP($B20,'[1]FCST MKT UNITED 26'!$B$4:$O$22,K$3,0) -> #REF! | L20: =VLOOKUP($B20,'[1]FCST MKT UNITED 26'!$B$4:$O$22,L$3,0) -> #REF! | M20: =VLOOKUP($B20,'[1]FCST MKT UNITED 26'!$B$4:$O$22,M$3,0) -> #REF! | N20: =VLOOKUP($B20,'[1]FCST MKT UNITED 26'!$B$4:$O$22,N$3,0) -> #REF! | O20: =+SUM(C20:N20) -> #REF! | P20: Desde marzo queda igual que el plan en todos los meses | AE20: -17.246628 | AF20: =IF((+IFERROR((AE20/$AE$7),0))<=-200%,"-200%",(+IFERROR((AE20/$AE$7),0))) -> (4%) | AG20: =VLOOKUP(AK20,$B$27:$O$45,14,0) -> (17.8) | AH20: =IF((+IFERROR((AG20/$AG$7),0))<=-200%,"-200%",(+IFERROR((AG20/$AG$7),0))) -> (4%) | AI20: =VLOOKUP(AK20,$B$4:$O$22,14,0) -> #REF! | AJ20: =IF((+IFERROR((AI20/$AI$7),0))<=-200%,"-200%",(+IFERROR((AI20/$AI$7),0))) -> 0% | AK20: Gastos Staff | AL20: =+AI20-AG20 -> #REF! | AM20: =IF((IFERROR(IF(ABS(AL20/AG20)>=9.99,IF(AL20>0,9.99,-9.99),AL20/ABS(AG20)),IF(AL20=0,0,AL20/ABS(AL20))))<=-200%,"-200%",(IFERROR(IF(ABS(AL20/AG20)>=9.99,IF(AL20>0,9.99,-9.99),AL20/ABS(AG20)),IF(AL20=0,0,AL20/ABS(AL20))))) -> #REF! | AN20: =AI20-AE20 -> #REF! | AO20: =IF((IFERROR(IF(ABS(AN20/AE20)>=9.99,IF(AN20>0,9.99,-9.99),AN20/ABS(AE20)),IF(AN20=0,0,AN20/ABS(AN20))))<=-200%,"(200%)",(IFERROR(IF(ABS(AN20/AE20)>=9.99,IF(AN20>0,9.99,-9.99),AN20/ABS(AE20)),IF(AN20=0,0,AN20/ABS(AN20))))) -> #REF!
B21: Total Gastos | C21: =+SUM(C13:C20) -> (7.0) | D21: =+SUM(D13:D20) -> (6.7) | E21: =+SUM(E13:E20) -> (6.5) | F21: =+SUM(F13:F20) -> (6.7) | G21: =+SUM(G13:G20) -> (6.7) | H21: =+SUM(H13:H20) -> #REF! | I21: =+SUM(I13:I20) -> #REF! | J21: =+SUM(J13:J20) -> #REF! | ... O21: =+SUM(O13:O20) -> #REF! | AE21: =+SUM(AE13:AE20) -> (76.1) | AF21: =IF((+IFERROR((AE21/$AE$7),0))<=-200%,"-200%",(+IFERROR((AE21/$AE$7),0))) -> (16%) | AG21: =+SUM(AG13:AG20) -> (87.8) | AH21: =IF((+IFERROR((AG21/$AG$7),0))<=-200%,"-200%",(+IFERROR((AG21/$AG$7),0))) -> (18%) | AI21: =+SUM(AI13:AI20) -> #REF! | AJ21: =IF((+IFERROR((AI21/$AI$7),0))<=-200%,"-200%",(+IFERROR((AI21/$AI$7),0))) -> 0% | AK21: Total Gastos | AL21: =+AI21-AG21 -> #REF! | AM21: =IF((IFERROR(IF(ABS(AL21/AG21)>=9.99,IF(AL21>0,9.99,-9.99),AL21/ABS(AG21)),IF(AL21=0,0,AL21/ABS(AL21))))<=-200%,"-200%",(IFERROR(IF(ABS(AL21/AG21)>=9.99,IF(AL21>0,9.99,-9.99),AL21/ABS(AG21)),IF(AL21=0,0,AL21/ABS(AL21))))) -> #REF! | AN21: =AI21-AE21 -> #REF! | AO21: =IF((IFERROR(IF(ABS(AN21/AE21)>=9.99,IF(AN21>0,9.99,-9.99),AN21/ABS(AE21)),IF(AN21=0,0,AN21/ABS(AN21))))<=-200%,"(200%)",(IFERROR(IF(ABS(AN21/AE21)>=9.99,IF(AN21>0,9.99,-9.99),AN21/ABS(AE21)),IF(AN21=0,0,AN21/ABS(AN21))))) -> #REF!
B22: Contribución Neta $ | C22: =C12+C21 -> (1.4) | D22: =D12+D21 -> 6.2 | E22: =E12+E21 -> 2.6 | F22: =F12+F21 -> 8.8 | G22: =G12+G21 -> 11.0 | H22: =H12+H21 -> #REF! | I22: =I12+I21 -> #REF! | J22: =J12+J21 -> #REF! | ... O22: =O12+O21 -> #REF! | AE22: =+AE21+AE12 -> 70.0 | AF22: =IF((+IFERROR((AE22/$AE$7),0))<=-200%,"-200%",(+IFERROR((AE22/$AE$7),0))) -> 15% | AG22: =AG12+AG21 -> 107.2 | AH22: =IF((+IFERROR((AG22/$AG$7),0))<=-200%,"-200%",(+IFERROR((AG22/$AG$7),0))) -> 21% | AI22: =AI12+AI21 -> #REF! | AJ22: =IF((+IFERROR((AI22/$AI$7),0))<=-200%,"-200%",(+IFERROR((AI22/$AI$7),0))) -> 0% | AK22: Contribución Neta | AL22: =+AI22-AG22 -> #REF! | AM22: =IF((IFERROR(IF(ABS(AL22/AG22)>=9.99,IF(AL22>0,9.99,-9.99),AL22/ABS(AG22)),IF(AL22=0,0,AL22/ABS(AL22))))<=-200%,"-200%",(IFERROR(IF(ABS(AL22/AG22)>=9.99,IF(AL22>0,9.99,-9.99),AL22/ABS(AG22)),IF(AL22=0,0,AL22/ABS(AL22))))) -> #REF! | AN22: =AI22-AE22 -> #REF! | AO22: =IF((IFERROR(IF(ABS(AN22/AE22)>=9.99,IF(AN22>0,9.99,-9.99),AN22/ABS(AE22)),IF(AN22=0,0,AN22/ABS(AN22))))<=-200%,"(200%)",(IFERROR(IF(ABS(AN22/AE22)>=9.99,IF(AN22>0,9.99,-9.99),AN22/ABS(AE22)),IF(AN22=0,0,AN22/ABS(AN22))))) -> #REF!
B24: % Margen | C24: =C22/C7 -> (8%) | D24: =D22/D7 -> 19% | E24: =E22/E7 -> 10% | F24: =F22/F7 -> 22% | G24: =G22/G7 -> 26% | H24: =H22/H7 -> #REF! | I24: =I22/I7 -> #REF! | J24: =J22/J7 -> #REF! | ... O24: =O22/O7 -> #REF!
B27: Presupuesto 2026 | C27: 46023 | D27: 46054 | E27: 46082 | F27: 46113 | G27: 46143 | H27: 46174 | I27: 46204 | J27: 46235 | K27: 46266 | L27: 46296 | M27: 46327 | N27: 46357 | O27: Total
B28: Ingresos Internos | C28: 24.12836 | D28: 23.935514 | E28: 21.375945 | F28: 27.733583 | G28: 38.235001 | H28: 33.598168 | I28: 28.651672 | J28: 42.118013 | K28: 41.65958 | L28: 40.017488 | M28: 41.815298 | N28: 73.255224 | O28: =+SUM(C28:N28) -> 436.5 | R28: % | S28: 46023 | T28: 46054 | U28: 46082 | V28: 46113 | W28: 46143 | X28: 46174 | Y28: 46204 | Z28: 46235 | AA28: 46266 | AB28: 46296 | AC28: 46327 | AD28: 46357
B29: Ingresos Externos | C29: 1.0035979 | D29: 1.58533 | E29: 2.3324669 | F29: 2.7162186 | G29: 3.4036958 | H29: 2.6425153 | I29: 3.0059344 | J29: 4.1537398 | K29: 6.8141253 | L29: 10.714125 | M29: 13.314125 | N29: 13.314125 | O29: =+SUM(C29:N29) -> 65.0 | R29: Ingresos Internos | S29: =C5/C28 -> 51% | T29: =D5/D28 -> 122% | U29: =E5/E28 -> 113% | V29: =F5/F28 -> 136% | W29: =G5/G28 -> 104% | X29: =H5/H28 -> #REF! | Y29: =I5/I28 -> #REF! | Z29: =J5/J28 -> #REF! | ... AD29: =N5/N28 -> #REF!
B30: Total Ingresos | C30: =C28+C29 -> 25.1 | D30: =D28+D29 -> 25.5 | E30: =E29+E28 -> 23.7 | F30: =F29+F28 -> 30.4 | G30: =G29+G28 -> 41.6 | H30: =H29+H28 -> 36.2 | I30: =I29+I28 -> 31.7 | J30: =J29+J28 -> 46.3 | K30: =K29+K28 -> 48.5 | L30: =L29+L28 -> 50.7 | ... O30: =O29+O28 -> 501.5 | R30: Ingresos Externos | S30: =C6/C29 -> 467% | T30: =D6/D29 -> 192% | U30: =E6/E29 -> 28% | V30: 0.55 | W30: 0.55 | X30: 0.55 | Y30: 0.55 | Z30: 0.55 | AA30: 0.55 | AB30: 0.55 | AC30: 0.55 | AD30: 0.55
B31: Activaciones | C31: -15.079175 | D31: -15.312506 | E31: -14.225047 | F31: -18.269881 | G31: -24.983218 | H31: -21.74441 | I31: -18.994564 | J31: -27.763051 | K31: -29.084223 | L31: -30.438968 | M31: -33.077654 | N31: -51.941609 | O31: =+SUM(C31:N31) -> (300.9)
B32: Comisiones | C32: -0.051592962 | D32: -0.081498644 | E32: -0.11990746 | F32: -0.13963536 | G32: -0.17497719 | H32: -0.13584643 | I32: -0.15452907 | J32: -0.21353546 | K32: -0.35030056 | L32: -0.55079176 | M32: -0.68445256 | N32: -0.68445256 | O32: =+SUM(C32:N32) -> (3.3) | R32: Activaciones | U32: =E31/E30-6% -> -66.0% | V32: =U32 -> -66.0% | W32: =V32 -> -66.0% | X32: =W32 -> -66.0% | Y32: =X32 -> -66.0% | Z32: =Y32 -> -66.0% | AA32: =Z32 -> -66.0% | AB32: =AA32 -> -66.0% | AC32: =AB32 -> -66.0% | AD32: =AC32 -> -66.0%
B33: Participación Socios | C33: -0.035326647 | D33: -0.055803615 | E33: -0.082102834 | F33: -0.095610894 | G33: -0.11981009 | H33: -0.093016538 | I33: -0.10580889 | J33: -0.14621164 | K33: -0.23985721 | L33: -0.37713721 | M33: -0.46865721 | N33: -0.46865721 | O33: =+SUM(C33:N33) -> (2.3) | R33: Comisiones | S33: =C9/C32 -> 82% | T33: =D9/D32 -> 28% | U33: =AVERAGE(S33:T33) -> 55% | V33: =U33 -> 55% | W33: =V33 -> 55% | X33: =W33 -> 55% | Y33: =X33 -> 55% | Z33: =Y33 -> 55% | AA33: =Z33 -> 55% | AB33: =AA33 -> 55% | AC33: =AB33 -> 55% | AD33: =AC33 -> 55%
B34: Costos Totales | C34: =SUM(C31:C33) -> (15.2) | D34: =SUM(D31:D33) -> (15.4) | E34: =SUM(E31:E33) -> (14.4) | F34: =SUM(F31:F33) -> (18.5) | G34: =SUM(G31:G33) -> (25.3) | H34: =SUM(H31:H33) -> (22.0) | I34: =SUM(I31:I33) -> (19.3) | J34: =SUM(J31:J33) -> (28.1) | ... O34: =SUM(O31:O33) -> (306.5) | R34: Participación Socios
B35: Contribución Bruta | C35: =C30+C34 -> 10.0 | D35: =D30+D34 -> 10.1 | E35: =E30+E34 -> 9.3 | F35: =F30+F34 -> 11.9 | G35: =G30+G34 -> 16.4 | H35: =H30+H34 -> 14.3 | I35: =I30+I34 -> 12.4 | J35: =J30+J34 -> 18.1 | ... O35: =O30+O34 -> 195.0 | R35: Costos Totales
B36: Personal | C36: -4.1316957 | D36: -4.1316957 | E36: -4.1316957 | F36: -4.1316957 | G36: -4.1316957 | H36: -4.1316957 | I36: -4.1316957 | J36: -4.1316957 | K36: -4.1316957 | L36: -4.1316957 | M36: -4.1316957 | N36: -4.1316957 | O36: =+SUM(C36:N36) -> (49.6)
B37: Operación | C37: -0.667 | D37: -1.067 | E37: -0.167 | F37: -0.417 | G37: -0.424 | H37: -0.41763621 | I37: -0.267 | J37: -0.317 | K37: -0.267 | L37: -0.267 | M37: -0.274 | N37: -0.267 | O37: =+SUM(C37:N37) -> (4.8) | R37: Personal
B38: Mercadotecnia | C38: -0.151769 | D38: -0.18338 | E38: -0.59204677 | F38: -0.24869 | G38: -0.13869 | H38: -0.13869 | I38: -0.13869 | J38: -0.13869 | K38: -0.13869 | L38: -0.17369 | M38: -0.13869 | N38: -0.13869 | O38: =+SUM(C38:N38) -> (2.3) | R38: Operación
B39: Renta, Luz y Teléfono | C39: -0.3868168 | D39: -0.36747596 | E39: -0.36747596 | F39: -0.36747596 | G39: -0.36747596 | H39: -0.36747596 | I39: -0.36747596 | J39: -0.36747596 | K39: -0.36747596 | L39: -0.36747596 | M39: -0.36747596 | N39: -0.36747596 | O39: =+SUM(C39:N39) -> (4.4) | R39: Mercadotecnia
B40: Gastos de despacho GS | C40: -0.27331933 | D40: -0.234205 | E40: -0.20044467 | F40: -0.21160668 | G40: -0.20801397 | H40: -0.21403749 | I40: -0.21214275 | J40: -0.21182125 | K40: -0.20824344 | L40: -0.22866781 | M40: -0.20767621 | N40: -0.20767621 | O40: =+SUM(C40:N40) -> (2.6) | R40: Renta, Luz y Teléfono
B41: Costo de Activo | C41: -0.00016344563 | D41: -0.00016344563 | E41: -0.00016485 | F41: -0.0001638 | G41: -0.0001533 | H41: -0.00016065 | I41: -0.00067935 | J41: -0.00067935 | K41: -0.0021002625 | L41: -0.029884233 | M41: -0.029884233 | N41: -0.029884233 | O41: =+SUM(C41:N41) -> (0.1) | R41: Gastos de despacho GS
B42: Gastos Ventas | C42: -0.51010665 | D42: -0.51010665 | E42: -0.51010665 | F42: -0.51010665 | G42: -0.51010665 | H42: -0.51010665 | I42: -0.51010665 | J42: -0.51010665 | K42: -0.51010665 | L42: -0.51010665 | M42: -0.51010665 | N42: -0.51010665 | O42: =+SUM(C42:N42) -> (6.1) | R42: Costo de Activo
B43: Gastos Staff | C43: -1.3522168 | D43: -1.4532884 | E43: -1.4944164 | F43: -1.4322186 | G43: -1.440031 | H43: -1.4367408 | I43: -1.476321 | J43: -1.4611031 | K43: -1.55573 | L43: -1.527619 | M43: -1.6039685 | N43: -1.6038162 | O43: =+SUM(C43:N43) -> (17.8) | R43: Gastos Ventas | S43: =C19/C42 -> 103% | T43: =D19/D42 -> 91%
...

Sheet Mkt United + Troader 26
B1: MARKETING UNITED + TROADER REAL 2024 | Q1: MARKETING UNITED + TROADER REAL 2025 | AF1: MARKETING UNITED + TROADER PRESUPUESTO 2026 | AU1: MARKETING UNITED + TROADER FORECAST 2026 | BK1: MARKETING UNITED + TROADER
BK3: Real 2025 | BM3: Plan 2026 | BO3: Fcst 2026 | BQ3: Conceptos | BR3: Variaciones
BR4: Fcst 2026 vs Ppto 2026 | BT4: Fcst 2026 vs Real 2025
B5: Real 2024 | C5: 45292 | D5: 45323 | E5: 45352 | F5: 45383 | G5: 45413 | H5: 45444 | I5: 45474 | J5: 45505 | K5: 45536 | L5: 45566 | M5: 45597 | N5: 45627 | O5: Total | Q5: Real 2025 | R5: 46023 | S5: 46054 | T5: 46082 | U5: 46113 | V5: 46143 | W5: 46174 | X5: 46204 | Y5: 46235 | Z5: 46266 | AA5: 46296 | AB5: 46327 | AC5: 46357 | AD5: Total | AF5: Presupuesto 2026 | AG5: 46023 | AH5: 46054 | AI5: 46082 | AJ5: 46113 | AK5: 46143 | AL5: 46174 | AM5: 46204 | AN5: 46235 | AO5: 46266 | AP5: 46296 | AQ5: 46327 | AR5: 46357 | AS5: Total | AU5: Forecast 2026 | AV5: 46023 | AW5: 46054 | AX5: 46082 | AY5: 46113 | AZ5: 46143 | BA5: 46174 | BB5: 46204 | BC5: 46235 | BD5: 46266 | BE5: 46296 | BF5: 46327 | BG5: 46357 | BH5: Total | BK5: $ | BL5: % | BM5: $ | BN5: % | BO5: $ | BP5: % | BR5: $ | BS5: % | BT5: $ | BU5: %
B6: Ingresos Internos | C6: =SUMIF($B$38:$B$86,$B6,C$38:C$86) -> 35.8 | D6: =SUMIF($B$38:$B$86,$B6,D$38:D$86) -> 39.6 | E6: =SUMIF($B$38:$B$86,$B6,E$38:E$86) -> 48.7 | F6: =SUMIF($B$38:$B$86,$B6,F$38:F$86) -> 68.7 | G6: =SUMIF($B$38:$B$86,$B6,G$38:G$86) -> 63.1 | H6: =SUMIF($B$38:$B$86,$B6,H$38:H$86) -> 73.1 | I6: =SUMIF($B$38:$B$86,$B6,I$38:I$86) -> 63.3 | J6: =SUMIF($B$38:$B$86,$B6,J$38:J$86) -> 70.9 | ... N6: =SUMIF($B$38:$B$86,$B6,N$38:N$86) -> 89.6 | O6: =+SUM(C6:N6) -> 810.4 | Q6: Ingresos Internos | R6: =SUMIF($Q$38:$Q$86,$Q6,R$38:R$86) -> 51.2 | S6: =SUMIF($Q$38:$Q$86,$Q6,S$38:S$86) -> 59.5 | T6: =SUMIF($Q$38:$Q$86,$Q6,T$38:T$86) -> 58.3 | U6: =SUMIF($Q$38:$Q$86,$Q6,U$38:U$86) -> 65.3 | V6: =SUMIF($Q$38:$Q$86,$Q6,V$38:V$86) -> 62.5 | W6: =SUMIF($Q$38:$Q$86,$Q6,W$38:W$86) -> 66.1 | X6: =SUMIF($Q$38:$Q$86,$Q6,X$38:X$86) -> 70.7 | Y6: =SUMIF($Q$38:$Q$86,$Q6,Y$38:Y$86) -> 75.1 | ... AC6: =SUMIF($Q$38:$Q$86,$Q6,AC$38:AC$86) -> 72.3 | AD6: =+SUM(R6:AC6) -> 809.3 | AF6: Ingresos Internos | AG6: =SUMIF($AF$38:$AF$86,$AF6,AG$38:AG$86) -> 28.5 | AH6: =SUMIF($AF$38:$AF$86,$AF6,AH$38:AH$86) -> 27.7 | AI6: =SUMIF($AF$38:$AF$86,$AF6,AI$38:AI$86) -> 25.7 | AJ6: =SUMIF($AF$38:$AF$86,$AF6,AJ$38:AJ$86) -> 31.8 | AK6: =SUMIF($AF$38:$AF$86,$AF6,AK$38:AK$86) -> 42.3 | AL6: =SUMIF($AF$38:$AF$86,$AF6,AL$38:AL$86) -> 38.3 | AM6: =SUMIF($AF$38:$AF$86,$AF6,AM$38:AM$86) -> 32.9 | AN6: =SUMIF($AF$38:$AF$86,$AF6,AN$38:AN$86) -> 46.4 | ... AR6: =SUMIF($AF$38:$AF$86,$AF6,AR$38:AR$86) -> 78.0 | AS6: =+SUM(AG6:AR6) -> 489.0 | AU6: Ingresos Internos | AV6: =SUMIF($AU$38:$AU$86,$AU6,AV$38:AV$86) -> #REF! | AW6: =SUMIF($AU$38:$AU$86,$AU6,AW$38:AW$86) -> #REF! | AX6: =SUMIF($AU$38:$AU$86,$AU6,AX$38:AX$86) -> #REF! | AY6: =SUMIF($AU$38:$AU$86,$AU6,AY$38:AY$86) -> #REF! | AZ6: =SUMIF($AU$38:$AU$86,$AU6,AZ$38:AZ$86) -> 40.8 | BA6: =SUMIF($AU$38:$AU$86,$AU6,BA$38:BA$86) -> 33.5 | BB6: =SUMIF($AU$38:$AU$86,$AU6,BB$38:BB$86) -> 30.3 | BC6: =SUMIF($AU$38:$AU$86,$AU6,BC$38:BC$86) -> 44.0 | ... BG6: =SUMIF($AU$38:$AU$86,$AU6,BG$38:BG$86) -> 70.5 | BH6: =+SUM(AV6:BG6) -> #REF! | BK6: =VLOOKUP(BQ6,$Q$5:$AD$29,14,0) -> 809.3 | BL6: =IF((+IFERROR((BK6/$BK$8),0))<=-200%,"-200%",(+IFERROR((BK6/$BK$8),0))) -> 98% | BM6: =VLOOKUP(BQ6,$AF$5:$AS$29,14,0) -> 489.0 | BN6: =IF((+IFERROR((BM6/$BM$8),0))<=-200%,"-200%",(+IFERROR((BM6/$BM$8),0))) -> 87% | BO6: =VLOOKUP(BQ6,$AU$5:$BH$29,14,0) -> #REF! | BP6: =IF((+IFERROR((BO6/$BO$8),0))<=-200%,"-200%",(+IFERROR((BO6/$BO$8),0))) -> 0% | BQ6: Ingresos Internos | BR6: =+BO6-BM6 -> #REF! | BS6: =IF((IFERROR(IF(ABS(BR6/BM6)>=9.99,IF(BR6>0,9.99,-9.99),BR6/ABS(BM6)),IF(BR6=0,0,BR6/ABS(BR6))))<=-200%,"-200%",(IFERROR(IF(ABS(BR6/BM6)>=9.99,IF(BR6>0,9.99,-9.99),BR6/ABS(BM6)),IF(BR6=0,0,BR6/ABS(BR6))))) -> #REF! | BT6: =+BO6-BK6 -> #REF! | BU6: =IF((IFERROR(IF(ABS(BT6/BK6)>=9.99,IF(BT6>0,9.99,-9.99),BT6/ABS(BK6)),IF(BT6=0,0,BT6/ABS(BT6))))<=-200%,"-200%",(IFERROR(IF(ABS(BT6/BK6)>=9.99,IF(BT6>0,9.99,-9.99),BT6/ABS(BK6)),IF(BT6=0,0,BT6/ABS(BT6))))) -> #REF!
B7: Ingresos Externos | C7: =SUMIF($B$38:$B$86,$B7,C$38:C$86) -> 3.4 | D7: =SUMIF($B$38:$B$86,$B7,D$38:D$86) -> 3.7 | E7: =SUMIF($B$38:$B$86,$B7,E$38:E$86) -> 2.3 | F7: =SUMIF($B$38:$B$86,$B7,F$38:F$86) -> 0.5 | G7: =SUMIF($B$38:$B$86,$B7,G$38:G$86) -> 1.3 | H7: =SUMIF($B$38:$B$86,$B7,H$38:H$86) -> 1.1 | I7: =SUMIF($B$38:$B$86,$B7,I$38:I$86) -> 0.2 | J7: =SUMIF($B$38:$B$86,$B7,J$38:J$86) -> 0.7 | ... N7: =SUMIF($B$38:$B$86,$B7,N$38:N$86) -> 0.1 | O7: =+SUM(C7:N7) -> 17.2 | Q7: Ingresos Externos | R7: =SUMIF($Q$38:$Q$86,$Q7,R$38:R$86) -> 0.4 | S7: =SUMIF($Q$38:$Q$86,$Q7,S$38:S$86) -> 0.3 | T7: =SUMIF($Q$38:$Q$86,$Q7,T$38:T$86) -> 3.2 | U7: =SUMIF($Q$38:$Q$86,$Q7,U$38:U$86) -> 2.5 | V7: =SUMIF($Q$38:$Q$86,$Q7,V$38:V$86) -> 2.5 | W7: =SUMIF($Q$38:$Q$86,$Q7,W$38:W$86) -> 1.6 | X7: =SUMIF($Q$38:$Q$86,$Q7,X$38:X$86) -> 1.6 | Y7: =SUMIF($Q$38:$Q$86,$Q7,Y$38:Y$86) -> 1.2 | ... AC7: =SUMIF($Q$38:$Q$86,$Q7,AC$38:AC$86) -> 2.2 | AD7: =+SUM(R7:AC7) -> 18.3 | AF7: Ingresos Externos | AG7: =SUMIF($AF$38:$AF$86,$AF7,AG$38:AG$86) -> 1.0 | AH7: =SUMIF($AF$38:$AF$86,$AF7,AH$38:AH$86) -> 1.6 | AI7: =SUMIF($AF$38:$AF$86,$AF7,AI$38:AI$86) -> 2.3 | AJ7: =SUMIF($AF$38:$AF$86,$AF7,AJ$38:AJ$86) -> 2.7 | AK7: =SUMIF($AF$38:$AF$86,$AF7,AK$38:AK$86) -> 3.4 | AL7: =SUMIF($AF$38:$AF$86,$AF7,AL$38:AL$86) -> 3.5 | AM7: =SUMIF($AF$38:$AF$86,$AF7,AM$38:AM$86) -> 3.9 | AN7: =SUMIF($AF$38:$AF$86,$AF7,AN$38:AN$86) -> 5.1 | ... AR7: =SUMIF($AF$38:$AF$86,$AF7,AR$38:AR$86) -> 14.3 | AS7: =+SUM(AG7:AR7) -> 71.7 | AU7: Ingresos Externos | AV7: =SUMIF($AU$38:$AU$86,$AU7,AV$38:AV$86) -> #REF! | AW7: =SUMIF($AU$38:$AU$86,$AU7,AW$38:AW$86) -> #REF! | AX7: =SUMIF($AU$38:$AU$86,$AU7,AX$38:AX$86) -> #REF! | AY7: =SUMIF($AU$38:$AU$86,$AU7,AY$38:AY$86) -> #REF! | AZ7: =SUMIF($AU$38:$AU$86,$AU7,AZ$38:AZ$86) -> 4.6 | BA7: =SUMIF($AU$38:$AU$86,$AU7,BA$38:BA$86) -> 7.8 | BB7: =SUMIF($AU$38:$AU$86,$AU7,BB$38:BB$86) -> 4.1 | BC7: =SUMIF($AU$38:$AU$86,$AU7,BC$38:BC$86) -> 0.1 | ... BG7: =SUMIF($AU$38:$AU$86,$AU7,BG$38:BG$86) -> 1.1 | BH7: =+SUM(AV7:BG7) -> #REF! | BK7: =VLOOKUP(BQ7,$Q$5:$AD$29,14,0) -> 18.3 | BL7: =IF((+IFERROR((BK7/$BK$8),0))<=-200%,"-200%",(+IFERROR((BK7/$BK$8),0))) -> 2% | BM7: =VLOOKUP(BQ7,$AF$5:$AS$29,14,0) -> 71.7 | BN7: =IF((+IFERROR((BM7/$BM$8),0))<=-200%,"-200%",(+IFERROR((BM7/$BM$8),0))) -> 13% | BO7: =VLOOKUP(BQ7,$AU$5:$BH$29,14,0) -> #REF! | BP7: =IF((+IFERROR((BO7/$BO$8),0))<=-200%,"-200%",(+IFERROR((BO7/$BO$8),0))) -> 0% | BQ7: Ingresos Externos | BR7: =+BO7-BM7 -> #REF! | BS7: =IF((IFERROR(IF(ABS(BR7/BM7)>=9.99,IF(BR7>0,9.99,-9.99),BR7/ABS(BM7)),IF(BR7=0,0,BR7/ABS(BR7))))<=-200%,"-200%",(IFERROR(IF(ABS(BR7/BM7)>=9.99,IF(BR7>0,9.99,-9.99),BR7/ABS(BM7)),IF(BR7=0,0,BR7/ABS(BR7))))) -> #REF! | BT7: =+BO7-BK7 -> #REF! | BU7: =IF((IFERROR(IF(ABS(BT7/BK7)>=9.99,IF(BT7>0,9.99,-9.99),BT7/ABS(BK7)),IF(BT7=0,0,BT7/ABS(BT7))))<=-200%,"-200%",(IFERROR(IF(ABS(BT7/BK7)>=9.99,IF(BT7>0,9.99,-9.99),BT7/ABS(BK7)),IF(BT7=0,0,BT7/ABS(BT7))))) -> #REF!
B8: Total Ingresos | C8: =C6+C7 -> 39.2 | D8: =D6+D7 -> 43.3 | E8: =E7+E6 -> 51.0 | F8: =F7+F6 -> 69.2 | G8: =G7+G6 -> 64.4 | H8: =H7+H6 -> 74.2 | I8: =I7+I6 -> 63.5 | J8: =J7+J6 -> 71.5 | K8: =K7+K6 -> 62.4 | L8: =L7+L6 -> 85.7 | ... O8: =O7+O6 -> 827.6 | Q8: Total Ingresos | R8: =R6+R7 -> 51.6 | S8: =S6+S7 -> 59.8 | T8: =T7+T6 -> 61.5 | U8: =U7+U6 -> 67.8 | V8: =V7+V6 -> 65.0 | W8: =W7+W6 -> 67.7 | X8: =X7+X6 -> 72.4 | Y8: =Y7+Y6 -> 76.2 | Z8: =Z7+Z6 -> 81.1 | AA8: =AA7+AA6 -> 63.3 | ... AD8: =AD7+AD6 -> 827.6 | AF8: Total Ingresos | AG8: =AG6+AG7 -> 29.5 | AH8: =AH6+AH7 -> 29.3 | AI8: =AI7+AI6 -> 28.1 | AJ8: =AJ7+AJ6 -> 34.5 | AK8: =AK7+AK6 -> 45.7 | AL8: =AL7+AL6 -> 41.8 | AM8: =AM7+AM6 -> 36.8 | AN8: =AN7+AN6 -> 51.5 | AO8: =AO7+AO6 -> 54.4 | AP8: =AP7+AP6 -> 56.1 | ... AS8: =AS7+AS6 -> 560.7 | AU8: Total Ingresos | AV8: =AV6+AV7 -> #REF! | AW8: =AW6+AW7 -> #REF! | AX8: =AX7+AX6 -> #REF! | AY8: =AY7+AY6 -> #REF! | AZ8: =AZ7+AZ6 -> 45.4 | BA8: =BA7+BA6 -> 41.2 | BB8: =BB7+BB6 -> 34.4 | BC8: =BC7+BC6 -> 44.2 | BD8: =BD7+BD6 -> 49.1 | BE8: =BE7+BE6 -> 48.9 | ... BH8: =BH7+BH6 -> #REF! | BK8: =SUM(BK6:BK7) -> 827.6 | BL8: =IF((+IFERROR((BK8/$BK$8),0))<=-200%,"-200%",(+IFERROR((BK8/$BK$8),0))) -> 100% | BM8: =SUM(BM6:BM7) -> 560.7 | BN8: =IF((+IFERROR((BM8/$BM$8),0))<=-200%,"-200%",(+IFERROR((BM8/$BM$8),0))) -> 100% | BO8: =SUM(BO6:BO7) -> #REF! | BP8: =IF((+IFERROR((BO8/$BO$8),0))<=-200%,"-200%",(+IFERROR((BO8/$BO$8),0))) -> 0% | BQ8: Total Ingresos | BR8: =+BO8-BM8 -> #REF! | BS8: =IF((IFERROR(IF(ABS(BR8/BM8)>=9.99,IF(BR8>0,9.99,-9.99),BR8/ABS(BM8)),IF(BR8=0,0,BR8/ABS(BR8))))<=-200%,"-200%",(IFERROR(IF(ABS(BR8/BM8)>=9.99,IF(BR8>0,9.99,-9.99),BR8/ABS(BM8)),IF(BR8=0,0,BR8/ABS(BR8))))) -> #REF! | BT8: =+BO8-BK8 -> #REF! | BU8: =IF((IFERROR(IF(ABS(BT8/BK8)>=9.99,IF(BT8>0,9.99,-9.99),BT8/ABS(BK8)),IF(BT8=0,0,BT8/ABS(BT8))))<=-200%,"-200%",(IFERROR(IF(ABS(BT8/BK8)>=9.99,IF(BT8>0,9.99,-9.99),BT8/ABS(BK8)),IF(BT8=0,0,BT8/ABS(BT8))))) -> #REF!
B9: Costo | C9: =SUMIF($B$38:$B$86,$B9,C$38:C$86) -> (18.1) | D9: =SUMIF($B$38:$B$86,$B9,D$38:D$86) -> (15.0) | E9: =SUMIF($B$38:$B$86,$B9,E$38:E$86) -> (16.9) | F9: =SUMIF($B$38:$B$86,$B9,F$38:F$86) -> (22.9) | G9: =SUMIF($B$38:$B$86,$B9,G$38:G$86) -> (22.5) | H9: =SUMIF($B$38:$B$86,$B9,H$38:H$86) -> (22.0) | I9: =SUMIF($B$38:$B$86,$B9,I$38:I$86) -> (27.1) | J9: =SUMIF($B$38:$B$86,$B9,J$38:J$86) -> (24.1) | ... N9: =SUMIF($B$38:$B$86,$B9,N$38:N$86) -> (32.2) | O9: =+SUM(C9:N9) -> (286.3) | Q9: Costo | R9: =SUMIF($Q$38:$Q$86,$Q9,R$38:R$86) -> (23.4) | S9: =SUMIF($Q$38:$Q$86,$Q9,S$38:S$86) -> (21.4) | T9: =SUMIF($Q$38:$Q$86,$Q9,T$38:T$86) -> (22.3) | U9: =SUMIF($Q$38:$Q$86,$Q9,U$38:U$86) -> (26.8) | V9: =SUMIF($Q$38:$Q$86,$Q9,V$38:V$86) -> (26.6) | W9: =SUMIF($Q$38:$Q$86,$Q9,W$38:W$86) -> (26.1) | X9: =SUMIF($Q$38:$Q$86,$Q9,X$38:X$86) -> (34.3) | Y9: =SUMIF($Q$38:$Q$86,$Q9,Y$38:Y$86) -> (28.3) | ... AC9: =SUMIF($Q$38:$Q$86,$Q9,AC$38:AC$86) -> (0.9) | AD9: =+SUM(R9:AC9) -> (251.9) | AF9: Costo | AG9: =SUMIF($AF$38:$AF$86,$AF9,AG$38:AG$86) -> (0.8) | AH9: =SUMIF($AF$38:$AF$86,$AF9,AH$38:AH$86) -> (1.3) | AI9: =SUMIF($AF$38:$AF$86,$AF9,AI$38:AI$86) -> (1.3) | AJ9: =SUMIF($AF$38:$AF$86,$AF9,AJ$38:AJ$86) -> (1.4) | AK9: =SUMIF($AF$38:$AF$86,$AF9,AK$38:AK$86) -> (1.4) | AL9: =SUMIF($AF$38:$AF$86,$AF9,AL$38:AL$86) -> (1.4) | AM9: =SUMIF($AF$38:$AF$86,$AF9,AM$38:AM$86) -> (1.4) | AN9: =SUMIF($AF$38:$AF$86,$AF9,AN$38:AN$86) -> (1.4) | ... AR9: =SUMIF($AF$38:$AF$86,$AF9,AR$38:AR$86) -> (1.6) | AS9: =+SUM(AG9:AR9) -> (16.6) | AU9: Costo | AV9: =SUMIF($AU$38:$AU$86,$AU9,AV$38:AV$86) -> #REF! | AW9: =SUMIF($AU$38:$AU$86,$AU9,AW$38:AW$86) -> #REF! | AX9: =SUMIF($AU$38:$AU$86,$AU9,AX$38:AX$86) -> #REF! | AY9: =SUMIF($AU$38:$AU$86,$AU9,AY$38:AY$86) -> #REF! | AZ9: =SUMIF($AU$38:$AU$86,$AU9,AZ$38:AZ$86) -> (1.0) | BA9: =SUMIF($AU$38:$AU$86,$AU9,BA$38:BA$86) -> (1.0) | BB9: =SUMIF($AU$38:$AU$86,$AU9,BB$38:BB$86) -> (1.0) | BC9: =SUMIF($AU$38:$AU$86,$AU9,BC$38:BC$86) -> (1.0) | ... BG9: =SUMIF($AU$38:$AU$86,$AU9,BG$38:BG$86) -> (1.0) | BH9: =+SUM(AV9:BG9) -> #REF! | BK9: =VLOOKUP(BQ9,$Q$5:$AD$29,14,0) -> (251.9) | BL9: =IF((+IFERROR((BK9/$BK$8),0))<=-200%,"-200%",(+IFERROR((BK9/$BK$8),0))) -> (30%) | BM9: =VLOOKUP(BQ9,$AF$5:$AS$29,14,0) -> (16.6) | BN9: =IF((+IFERROR((BM9/$BM$8),0))<=-200%,"-200%",(+IFERROR((BM9/$BM$8),0))) -> (3%) | BO9: =VLOOKUP(BQ9,$AU$5:$BH$29,14,0) -> #REF! | BP9: =IF((+IFERROR((BO9/$BO$8),0))<=-200%,"-200%",(+IFERROR((BO9/$BO$8),0))) -> 0% | BQ9: Costo | BR9: =+BO9-BM9 -> #REF! | BS9: =IF((IFERROR(IF(ABS(BR9/BM9)>=9.99,IF(BR9>0,9.99,-9.99),BR9/ABS(BM9)),IF(BR9=0,0,BR9/ABS(BR9))))<=-200%,"-200%",(IFERROR(IF(ABS(BR9/BM9)>=9.99,IF(BR9>0,9.99,-9.99),BR9/ABS(BM9)),IF(BR9=0,0,BR9/ABS(BR9))))) -> #REF! | BT9: =+BO9-BK9 -> #REF! | BU9: =IF((IFERROR(IF(ABS(BT9/BK9)>=9.99,IF(BT9>0,9.99,-9.99),BT9/ABS(BK9)),IF(BT9=0,0,BT9/ABS(BT9))))<=-200%,"-200%",(IFERROR(IF(ABS(BT9/BK9)>=9.99,IF(BT9>0,9.99,-9.99),BT9/ABS(BK9)),IF(BT9=0,0,BT9/ABS(BT9))))) -> #REF!
B10: Costo de nube | C10: =SUMIF($B$38:$B$86,$B10,C$38:C$86) -> - | D10: =SUMIF($B$38:$B$86,$B10,D$38:D$86) -> - | E10: =SUMIF($B$38:$B$86,$B10,E$38:E$86) -> - | F10: =SUMIF($B$38:$B$86,$B10,F$38:F$86) -> - | G10: =SUMIF($B$38:$B$86,$B10,G$38:G$86) -> - | H10: =SUMIF($B$38:$B$86,$B10,H$38:H$86) -> - | I10: =SUMIF($B$38:$B$86,$B10,I$38:I$86) -> - | J10: =SUMIF($B$38:$B$86,$B10,J$38:J$86) -> - | ... N10: =SUMIF($B$38:$B$86,$B10,N$38:N$86) -> - | O10: =+SUM(C10:N10) -> - | Q10: Costo de nube | R10: =SUMIF($Q$38:$Q$86,$Q10,R$38:R$86) -> (0.2) | S10: =SUMIF($Q$38:$Q$86,$Q10,S$38:S$86) -> (0.2) | T10: =SUMIF($Q$38:$Q$86,$Q10,T$38:T$86) -> (0.2) | U10: =SUMIF($Q$38:$Q$86,$Q10,U$38:U$86) -> (0.2) | V10: =SUMIF($Q$38:$Q$86,$Q10,V$38:V$86) -> (0.2) | W10: =SUMIF($Q$38:$Q$86,$Q10,W$38:W$86) -> (0.2) | X10: =SUMIF($Q$38:$Q$86,$Q10,X$38:X$86) -> (0.1) | Y10: =SUMIF($Q$38:$Q$86,$Q10,Y$38:Y$86) -> (0.2) | ... AC10: =SUMIF($Q$38:$Q$86,$Q10,AC$38:AC$86) -> - | AD10: =+SUM(R10:AC10) -> (1.5) | AF10: Costo de nube | AG10: =SUMIF($AF$38:$AF$86,$AF10,AG$38:AG$86) -> (0.1) | AH10: =SUMIF($AF$38:$AF$86,$AF10,AH$38:AH$86) -> (0.1) | AI10: =SUMIF($AF$38:$AF$86,$AF10,AI$38:AI$86) -> (0.1) | AJ10: =SUMIF($AF$38:$AF$86,$AF10,AJ$38:AJ$86) -> (0.1) | AK10: =SUMIF($AF$38:$AF$86,$AF10,AK$38:AK$86) -> (0.1) | AL10: =SUMIF($AF$38:$AF$86,$AF10,AL$38:AL$86) -> (0.1) | AM10: =SUMIF($AF$38:$AF$86,$AF10,AM$38:AM$86) -> (0.1) | AN10: =SUMIF($AF$38:$AF$86,$AF10,AN$38:AN$86) -> (0.1) | ... AR10: =SUMIF($AF$38:$AF$86,$AF10,AR$38:AR$86) -> (0.1) | AS10: =+SUM(AG10:AR10) -> (1.2) | AU10: Costo de nube | AV10: =SUMIF($AU$38:$AU$86,$AU10,AV$38:AV$86) -> #REF! | AW10: =SUMIF($AU$38:$AU$86,$AU10,AW$38:AW$86) -> #REF! | AX10: =SUMIF($AU$38:$AU$86,$AU10,AX$38:AX$86) -> #REF! | AY10: =SUMIF($AU$38:$AU$86,$AU10,AY$38:AY$86) -> #REF! | AZ10: =SUMIF($AU$38:$AU$86,$AU10,AZ$38:AZ$86) -> (0.1) | BA10: =SUMIF($AU$38:$AU$86,$AU10,BA$38:BA$86) -> (0.1) | BB10: =SUMIF($AU$38:$AU$86,$AU10,BB$38:BB$86) -> (0.1) | BC10: =SUMIF($AU$38:$AU$86,$AU10,BC$38:BC$86) -> (0.1) | ... BG10: =SUMIF($AU$38:$AU$86,$AU10,BG$38:BG$86) -> (0.1) | BH10: =+SUM(AV10:BG10) -> #REF! | BK10: =VLOOKUP(BQ10,$Q$5:$AD$29,14,0) -> (1.5) | BL10: =IF((+IFERROR((BK10/$BK$8),0))<=-200%,"-200%",(+IFERROR((BK10/$BK$8),0))) -> (0%) | BM10: =VLOOKUP(BQ10,$AF$5:$AS$29,14,0) -> (1.2) | BN10: =IF((+IFERROR((BM10/$BM$8),0))<=-200%,"-200%",(+IFERROR((BM10/$BM$8),0))) -> (0%) | BO10: =VLOOKUP(BQ10,$AU$5:$BH$29,14,0) -> #REF! | BP10: =IF((+IFERROR((BO10/$BO$8),0))<=-200%,"-200%",(+IFERROR((BO10/$BO$8),0))) -> 0% | BQ10: Costo de nube | BR10: =+BO10-BM10 -> #REF! | BS10: =IF((IFERROR(IF(ABS(BR10/BM10)>=9.99,IF(BR10>0,9.99,-9.99),BR10/ABS(BM10)),IF(BR10=0,0,BR10/ABS(BR10))))<=-200%,"-200%",(IFERROR(IF(ABS(BR10/BM10)>=9.99,IF(BR10>0,9.99,-9.99),BR10/ABS(BM10)),IF(BR10=0,0,BR10/ABS(BR10))))) -> #REF! | BT10: =+BO10-BK10 -> #REF! | BU10: =IF((IFERROR(IF(ABS(BT10/BK10)>=9.99,IF(BT10>0,9.99,-9.99),BT10/ABS(BK10)),IF(BT10=0,0,BT10/ABS(BT10))))<=-200%,"-200%",(IFERROR(IF(ABS(BT10/BK10)>=9.99,IF(BT10>0,9.99,-9.99),BT10/ABS(BK10)),IF(BT10=0,0,BT10/ABS(BT10))))) -> #REF!
B11: Activaciones | C11: =SUMIF($B$38:$B$86,$B11,C$38:C$86) -> (10.7) | D11: =SUMIF($B$38:$B$86,$B11,D$38:D$86) -> (17.4) | E11: =SUMIF($B$38:$B$86,$B11,E$38:E$86) -> (18.0) | F11: =SUMIF($B$38:$B$86,$B11,F$38:F$86) -> (37.9) | G11: =SUMIF($B$38:$B$86,$B11,G$38:G$86) -> (19.0) | H11: =SUMIF($B$38:$B$86,$B11,H$38:H$86) -> (38.3) | I11: =SUMIF($B$38:$B$86,$B11,I$38:I$86) -> (17.9) | J11: =SUMIF($B$38:$B$86,$B11,J$38:J$86) -> (27.3) | ... N11: =SUMIF($B$38:$B$86,$B11,N$38:N$86) -> (28.8) | O11: =+SUM(C11:N11) -> (324.3) | Q11: Activaciones | R11: =SUMIF($Q$38:$Q$86,$Q11,R$38:R$86) -> (15.6) | S11: =SUMIF($Q$38:$Q$86,$Q11,S$38:S$86) -> (19.3) | T11: =SUMIF($Q$38:$Q$86,$Q11,T$38:T$86) -> (21.0) | U11: =SUMIF($Q$38:$Q$86,$Q11,U$38:U$86) -> (18.5) | V11: =SUMIF($Q$38:$Q$86,$Q11,V$38:V$86) -> (21.5) | W11: =SUMIF($Q$38:$Q$86,$Q11,W$38:W$86) -> (20.1) | X11: =SUMIF($Q$38:$Q$86,$Q11,X$38:X$86) -> (17.4) | Y11: =SUMIF($Q$38:$Q$86,$Q11,Y$38:Y$86) -> (24.3) | ... AC11: =SUMIF($Q$38:$Q$86,$Q11,AC$38:AC$86) -> (72.9) | AD11: =+SUM(R11:AC11) -> (336.1) | AF11: Activaciones | AG11: =SUMIF($AF$38:$AF$86,$AF11,AG$38:AG$86) -> (15.1) | AH11: =SUMIF($AF$38:$AF$86,$AF11,AH$38:AH$86) -> (15.3) | AI11: =SUMIF($AF$38:$AF$86,$AF11,AI$38:AI$86) -> (14.2) | AJ11: =SUMIF($AF$38:$AF$86,$AF11,AJ$38:AJ$86) -> (18.3) | AK11: =SUMIF($AF$38:$AF$86,$AF11,AK$38:AK$86) -> (25.0) | AL11: =SUMIF($AF$38:$AF$86,$AF11,AL$38:AL$86) -> (21.7) | AM11: =SUMIF($AF$38:$AF$86,$AF11,AM$38:AM$86) -> (19.0) | AN11: =SUMIF($AF$38:$AF$86,$AF11,AN$38:AN$86) -> (27.8) | ... AR11: =SUMIF($AF$38:$AF$86,$AF11,AR$38:AR$86) -> (51.9) | AS11: =+SUM(AG11:AR11) -> (300.9) | AU11: Activaciones | AV11: =SUMIF($AU$38:$AU$86,$AU11,AV$38:AV$86) -> (11.4) | AW11: =SUMIF($AU$38:$AU$86,$AU11,AW$38:AW$86) -> (19.4) | AX11: =SUMIF($AU$38:$AU$86,$AU11,AX$38:AX$86) -> (15.6) | AY11: =SUMIF($AU$38:$AU$86,$AU11,AY$38:AY$86) -> (24.5) | AZ11: =SUMIF($AU$38:$AU$86,$AU11,AZ$38:AZ$86) -> (26.2) | BA11: =SUMIF($AU$38:$AU$86,$AU11,BA$38:BA$86) -> (23.2) | BB11: =SUMIF($AU$38:$AU$86,$AU11,BB$38:BB$86) -> (19.1) | BC11: =SUMIF($AU$38:$AU$86,$AU11,BC$38:BC$86) -> (25.3) | ... BG11: =SUMIF($AU$38:$AU$86,$AU11,BG$38:BG$86) -> (41.7) | BH11: =+SUM(AV11:BG11) -> (309.4) | BK11: =VLOOKUP(BQ11,$Q$5:$AD$29,14,0) -> (336.1) | BL11: =IF((+IFERROR((BK11/$BK$8),0))<=-200%,"-200%",(+IFERROR((BK11/$BK$8),0))) -> (41%) | BM11: =VLOOKUP(BQ11,$AF$5:$AS$29,14,0) -> (300.9) | BN11: =IF((+IFERROR((BM11/$BM$8),0))<=-200%,"-200%",(+IFERROR((BM11/$BM$8),0))) -> (54%) | BO11: =VLOOKUP(BQ11,$AU$5:$BH$29,14,0) -> (309.4) | BP11: =IF((+IFERROR((BO11/$BO$8),0))<=-200%,"-200%",(+IFERROR((BO11/$BO$8),0))) -> 0% | BQ11: Activaciones | BR11: =+BO11-BM11 -> (8.5) | BS11: =IF((IFERROR(IF(ABS(BR11/BM11)>=9.99,IF(BR11>0,9.99,-9.99),BR11/ABS(BM11)),IF(BR11=0,0,BR11/ABS(BR11))))<=-200%,"-200%",(IFERROR(IF(ABS(BR11/BM11)>=9.99,IF(BR11>0,9.99,-9.99),BR11/ABS(BM11)),IF(BR11=0,0,BR11/ABS(BR11))))) -> (3%) | BT11: =+BO11-BK11 -> 26.6 | BU11: =IF((IFERROR(IF(ABS(BT11/BK11)>=9.99,IF(BT11>0,9.99,-9.99),BT11/ABS(BK11)),IF(BT11=0,0,BT11/ABS(BT11))))<=-200%,"-200%",(IFERROR(IF(ABS(BT11/BK11)>=9.99,IF(BT11>0,9.99,-9.99),BT11/ABS(BK11)),IF(BT11=0,0,BT11/ABS(BT11))))) -> 8%
B12: Comisiones | C12: =SUMIF($B$38:$B$86,$B12,C$38:C$86) -> (0.0) | D12: =SUMIF($B$38:$B$86,$B12,D$38:D$86) -> - | E12: =SUMIF($B$38:$B$86,$B12,E$38:E$86) -> (0.1) | F12: =SUMIF($B$38:$B$86,$B12,F$38:F$86) -> (0.1) | G12: =SUMIF($B$38:$B$86,$B12,G$38:G$86) -> (0.0) | H12: =SUMIF($B$38:$B$86,$B12,H$38:H$86) -> (0.0) | I12: =SUMIF($B$38:$B$86,$B12,I$38:I$86) -> (0.0) | J12: =SUMIF($B$38:$B$86,$B12,J$38:J$86) -> (0.0) | ... N12: =SUMIF($B$38:$B$86,$B12,N$38:N$86) -> - | O12: =+SUM(C12:N12) -> (0.3) | Q12: Comisiones | R12: =SUMIF($Q$38:$Q$86,$Q12,R$38:R$86) -> - | S12: =SUMIF($Q$38:$Q$86,$Q12,S$38:S$86) -> - | T12: =SUMIF($Q$38:$Q$86,$Q12,T$38:T$86) -> (0.1) | U12: =SUMIF($Q$38:$Q$86,$Q12,U$38:U$86) -> (0.0) | V12: =SUMIF($Q$38:$Q$86,$Q12,V$38:V$86) -> (0.0) | W12: =SUMIF($Q$38:$Q$86,$Q12,W$38:W$86) -> (0.0) | X12: =SUMIF($Q$38:$Q$86,$Q12,X$38:X$86) -> (0.0) | Y12: =SUMIF($Q$38:$Q$86,$Q12,Y$38:Y$86) -> (0.0) | ... AC12: =SUMIF($Q$38:$Q$86,$Q12,AC$38:AC$86) -> (0.1) | AD12: =+SUM(R12:AC12) -> (0.4) | AF12: Comisiones | AG12: =SUMIF($AF$38:$AF$86,$AF12,AG$38:AG$86) -> (0.1) | AH12: =SUMIF($AF$38:$AF$86,$AF12,AH$38:AH$86) -> (0.1) | AI12: =SUMIF($AF$38:$AF$86,$AF12,AI$38:AI$86) -> (0.1) | AJ12: =SUMIF($AF$38:$AF$86,$AF12,AJ$38:AJ$86) -> (0.1) | AK12: =SUMIF($AF$38:$AF$86,$AF12,AK$38:AK$86) -> (0.2) | AL12: =SUMIF($AF$38:$AF$86,$AF12,AL$38:AL$86) -> (0.1) | AM12: =SUMIF($AF$38:$AF$86,$AF12,AM$38:AM$86) -> (0.2) | AN12: =SUMIF($AF$38:$AF$86,$AF12,AN$38:AN$86) -> (0.2) | ... AR12: =SUMIF($AF$38:$AF$86,$AF12,AR$38:AR$86) -> (0.7) | AS12: =+SUM(AG12:AR12) -> (3.3) | AU12: Comisiones | AV12: =SUMIF($AU$38:$AU$86,$AU12,AV$38:AV$86) -> (0.0) | AW12: =SUMIF($AU$38:$AU$86,$AU12,AW$38:AW$86) -> (0.0) | AX12: =SUMIF($AU$38:$AU$86,$AU12,AX$38:AX$86) -> (0.0) | AY12: =SUMIF($AU$38:$AU$86,$AU12,AY$38:AY$86) -> (0.0) | AZ12: =SUMIF($AU$38:$AU$86,$AU12,AZ$38:AZ$86) -> (0.2) | BA12: =SUMIF($AU$38:$AU$86,$AU12,BA$38:BA$86) -> (0.2) | BB12: =SUMIF($AU$38:$AU$86,$AU12,BB$38:BB$86) -> (0.1) | BC12: =SUMIF($AU$38:$AU$86,$AU12,BC$38:BC$86) -> (0.0) | ... BG12: =SUMIF($AU$38:$AU$86,$AU12,BG$38:BG$86) -> (0.0) | BH12: =+SUM(AV12:BG12) -> (0.9) | BK12: =VLOOKUP(BQ12,$Q$5:$AD$29,14,0) -> (0.4) | BL12: =IF((+IFERROR((BK12/$BK$8),0))<=-200%,"-200%",(+IFERROR((BK12/$BK$8),0))) -> (0%) | BM12: =VLOOKUP(BQ12,$AF$5:$AS$29,14,0) -> (3.3) | BN12: =IF((+IFERROR((BM12/$BM$8),0))<=-200%,"-200%",(+IFERROR((BM12/$BM$8),0))) -> (1%) | BO12: =VLOOKUP(BQ12,$AU$5:$BH$29,14,0) -> (0.9) | BP12: =IF((+IFERROR((BO12/$BO$8),0))<=-200%,"-200%",(+IFERROR((BO12/$BO$8),0))) -> 0% | BQ12: Comisiones | BR12: =+BO12-BM12 -> 2.5 | BS12: =IF((IFERROR(IF(ABS(BR12/BM12)>=9.99,IF(BR12>0,9.99,-9.99),BR12/ABS(BM12)),IF(BR12=0,0,BR12/ABS(BR12))))<=-200%,"-200%",(IFERROR(IF(ABS(BR12/BM12)>=9.99,IF(BR12>0,9.99,-9.99),BR12/ABS(BM12)),IF(BR12=0,0,BR12/ABS(BR12))))) -> 74% | BT12: =+BO12-BK12 -> (0.4) | BU12: =IF((IFERROR(IF(ABS(BT12/BK12)>=9.99,IF(BT12>0,9.99,-9.99),BT12/ABS(BK12)),IF(BT12=0,0,BT12/ABS(BT12))))<=-200%,"-200%",(IFERROR(IF(ABS(BT12/BK12)>=9.99,IF(BT12>0,9.99,-9.99),BT12/ABS(BK12)),IF(BT12=0,0,BT12/ABS(BT12))))) -> (92%)
